Workbook

Sheet 2026 토탈
Y1: 리그 | AB1: 리그 | AE1: 시즌 | AH1: 시즌 | BI1: K리그1 2026 리그순위 (2026-10-24 - 33R 종료)
A2: 대회 | B2: 일자 | C2: 요일 | D2: 라운드 | E2: 상대팀 | F2: 홈/원정 | G2: 득점 | H2: 실점 | I2: 결과 | J2: 중계채널 | K2: 해설 | L2: 캐스터 | M2: 득점1 | N2: 득점2 | O2: 득점3 | P2: 득점4 | Q2: 도움1 | R2: 도움2 | S2: 도움3 | T2: 도움4 | U2: 홈 관중 | V2: 주심 | X2: 이름 | Y2: 출전 | Z2: 선발 | AA2: 교체 | AB2: 득점 | AC2: 도움 | AD2: 합계 | AE2: 출전 | AF2: 선발 | AG2: 교체 | AH2: 득점 | AI2: 도움 | AJ2: 합계 | AM2: 홈/원정 | AN2: 경기 | AO2: 승 | AP2: 무 | AQ2: 패 | AR2: 승점 | AS2: 승률 | AT2: 득점 | AU2: 실점 | AV2: 득실 | AW2: 평균 승점 | AX2: 평균 득점 | AY2: 평균 실점 | BA2: 주심 | BB2: 경기 | BC2: 승 | BD2: 무 | BE2: 패 | BF2: 승점 | BG2: 승률 | BI2: 순위 | BJ2: 팀 | BK2: 경기 | BL2: 승 | BM2: 무 | BN2: 패 | BO2: 득점 | BP2: 실점 | BQ2: 득실 | BR2: 승점
A3: K리그 | B3: 2월 28일 | C3: 토 | D3: 1 | E3: 서울 | F3: 홈 | G3: 1 | H3: 2 | I3: 패 | M3: 무고사 | U3: 18108 | V3: 이동준 | X3: 무고사 | Y3: =Z3+AA3 -> 30 | Z3: =COUNTIF('출전기록 (26)'!C$2:M$39,'2026 토탈'!X3) -> 21 | AA3: =COUNTIF('출전기록 (26)'!N$2:S$39,'2026 토탈'!X3) -> 9 | AB3: =COUNTIF($M$3:$P$40,$X3) -> 14 | AC3: =COUNTIF($Q$3:$T$40,$X3) -> 2 | AD3: =AB3+AC3 -> 16 | AE3: =AF3+AG3 -> 30 | AF3: =COUNTIF('출전기록 (26)'!W$2:AG$7,'2026 토탈'!X3)+Z3 -> 21 | AG3: =COUNTIF('출전기록 (26)'!AH$2:AM$7,'2026 토탈'!X3)+AA3 -> 9 | AH3: =COUNTIF($M$3:$P$41,$X3) -> 14 | AI3: =COUNTIF($Q$3:$T$41,$X3) -> 2 | AJ3: =AH3+AI3 -> 16 | AM3: 홈 | AN3: =SUM(AO3:AQ3) -> 17 | AO3: =COUNTIFS($A$3:$A$40,"K리그",$F$3:$F$40,$AM3,$I$3:$I$40,AO$2) -> 7 | AP3: =COUNTIFS($A$3:$A$40,"K리그",$F$3:$F$40,$AM3,$I$3:$I$40,AP$2) -> 4 | AQ3: =COUNTIFS($A$3:$A$40,"K리그",$F$3:$F$40,$AM3,$I$3:$I$40,AQ$2) -> 6 | AR3: =AO3*3+AP3 -> 25 | AS3: =IFERROR(AO3/AN3,0) -> 0.41176471 | AT3: =SUMIFS($G$3:$G$40,$A$3:$A$40,"K리그",$F$3:$F$40,$AM3) -> 23 | AU3: =SUMIFS($H$3:$H$40,$A$3:$A$40,"K리그",$F$3:$F$40,$AM3) -> 17 | AV3: =AT3-AU3 -> 6 | AW3: =IFERROR(AR3/AN3,0) -> 1.4705882 | AX3: =IFERROR(AT3/AN3,0) -> 1.3529412 | AY3: =IFERROR(AU3/AN3,0) -> 1 | BA3: 이동준 | BB3: =SUM(BC3:BE3) -> 2 | BC3: =COUNTIFS($V$3:$V$40,$BA3,$I$3:$I$40,BC$2) -> 0 | BD3: =COUNTIFS($V$3:$V$40,$BA3,$I$3:$I$40,BD$2) -> 0 | BE3: =COUNTIFS($V$3:$V$40,$BA3,$I$3:$I$40,BE$2) -> 2 | BF3: =BC3*3+BD3 -> 0 | BG3: =IFERROR(BC3/BB3,0) -> 0 | BI3: 1 | BJ3: 서울 | BK3: 33 | BL3: 20 | BM3: 7 | BN3: 6 | BO3: 61 | BP3: 29 | BQ3: =BO3-BP3 -> 32 | BR3: 67
A4: K리그 | B4: 3월 7일 | C4: 토 | D4: 2 | E4: 광주 | F4: 원정 | G4: 2 | H4: 3 | I4: 패 | M4: 오후성 | N4: 서재민 | Q4: 김명순 | R4: 무고사 | V4: 최현재 | X4: 박승호 | Y4: =Z4+AA4 -> 14 | Z4: =COUNTIF('출전기록 (26)'!C$2:M$39,'2026 토탈'!X4) -> 6 | AA4: =COUNTIF('출전기록 (26)'!N$2:S$39,'2026 토탈'!X4) -> 8 | AB4: =COUNTIF($M$3:$P$40,$X4) -> 0 | AC4: =COUNTIF($Q$3:$T$40,$X4) -> 0 | AD4: =AB4+AC4 -> 0 | AE4: =AF4+AG4 -> 14 | AF4: =COUNTIF('출전기록 (26)'!W$2:AG$7,'2026 토탈'!X4)+Z4 -> 6 | AG4: =COUNTIF('출전기록 (26)'!AH$2:AM$7,'2026 토탈'!X4)+AA4 -> 8 | AH4: =COUNTIF($M$3:$P$41,$X4) -> 0 | AI4: =COUNTIF($Q$3:$T$41,$X4) -> 0 | AJ4: =AH4+AI4 -> 0 | AM4: 원정 | AN4: =SUM(AO4:AQ4) -> 16 | AO4: =COUNTIFS($A$3:$A$40,"K리그",$F$3:$F$40,$AM4,$I$3:$I$40,AO$2) -> 5 | AP4: =COUNTIFS($A$3:$A$40,"K리그",$F$3:$F$40,$AM4,$I$3:$I$40,AP$2) -> 6 | AQ4: =COUNTIFS($A$3:$A$40,"K리그",$F$3:$F$40,$AM4,$I$3:$I$40,AQ$2) -> 5 | AR4: =AO4*3+AP4 -> 21 | AS4: =IFERROR(AO4/AN4,0) -> 0.3125 | AT4: =SUMIFS($G$3:$G$40,$A$3:$A$40,"K리그",$F$3:$F$40,$AM4) -> 20 | AU4: =SUMIFS($H$3:$H$40,$A$3:$A$40,"K리그",$F$3:$F$40,$AM4) -> 18 | AV4: =AT4-AU4 -> 2 | AW4: =IFERROR(AR4/AN4,0) -> 1.3125 | AX4: =IFERROR(AT4/AN4,0) -> 1.25 | AY4: =IFERROR(AU4/AN4,0) -> 1.125 | BA4: 최현재 | BB4: =SUM(BC4:BE4) -> 3 | BC4: =COUNTIFS($V$3:$V$40,$BA4,$I$3:$I$40,BC$2) -> 1 | BD4: =COUNTIFS($V$3:$V$40,$BA4,$I$3:$I$40,BD$2) -> 1 | BE4: =COUNTIFS($V$3:$V$40,$BA4,$I$3:$I$40,BE$2) -> 1 | BF4: =BC4*3+BD4 -> 4 | BG4: =IFERROR(BC4/BB4,0) -> 0.33333333 | BI4: 2 | BJ4: 울산 | BK4: 33 | BL4: 15 | BM4: 6 | BN4: 12 | BO4: 52 | BP4: 47 | BQ4: =BO4-BP4 -> 5 | BR4: 51
A5: K리그 | B5: 3월 15일 | C5: 일 | D5: 3 | E5: 포항 | F5: 원정 | G5: 1 | H5: 1 | I5: 무 | M5: 무고사 | V5: 설태환 | X5: 이동률 | Y5: =Z5+AA5 -> 29 | Z5: =COUNTIF('출전기록 (26)'!C$2:M$39,'2026 토탈'!X5) -> 16 | AA5: =COUNTIF('출전기록 (26)'!N$2:S$39,'2026 토탈'!X5) -> 13 | AB5: =COUNTIF($M$3:$P$40,$X5) -> 4 | AC5: =COUNTIF($Q$3:$T$40,$X5) -> 2 | AD5: =AB5+AC5 -> 6 | AE5: =AF5+AG5 -> 29 | AF5: =COUNTIF('출전기록 (26)'!W$2:AG$7,'2026 토탈'!X5)+Z5 -> 16 | AG5: =COUNTIF('출전기록 (26)'!AH$2:AM$7,'2026 토탈'!X5)+AA5 -> 13 | AH5: =COUNTIF($M$3:$P$41,$X5) -> 4 | AI5: =COUNTIF($Q$3:$T$41,$X5) -> 2 | AJ5: =AH5+AI5 -> 6 | AM5: 총합 | AN5: =SUM(AN3:AN4) -> 33 | AO5: =SUM(AO3:AO4) -> 12 | AP5: =SUM(AP3:AP4) -> 10 | AQ5: =SUM(AQ3:AQ4) -> 11 | AR5: =SUM(AR3:AR4) -> 46 | AS5: =IFERROR(AO5/AN5,0) -> 0.36363636 | AT5: =SUM(AT3:AT4) -> 43 | AU5: =SUM(AU3:AU4) -> 35 | AV5: =SUM(AV3:AV4) -> 8 | AW5: =IFERROR(AR5/AN5,0) -> 1.3939394 | AX5: =IFERROR(AT5/AN5,0) -> 1.3030303 | AY5: =IFERROR(AU5/AN5,0) -> 1.0606061 | BA5: 설태환 | BB5: =SUM(BC5:BE5) -> 3 | BC5: =COUNTIFS($V$3:$V$40,$BA5,$I$3:$I$40,BC$2) -> 0 | BD5: =COUNTIFS($V$3:$V$40,$BA5,$I$3:$I$40,BD$2) -> 2 | BE5: =COUNTIFS($V$3:$V$40,$BA5,$I$3:$I$40,BE$2) -> 1 | BF5: =BC5*3+BD5 -> 2 | BG5: =IFERROR(BC5/BB5,0) -> 0 | BI5: 3 | BJ5: 대전 | BK5: 33 | BL5: 13 | BM5: 10 | BN5: 10 | BO5: 53 | BP5: 41 | BQ5: =BO5-BP5 -> 12 | BR5: 49
A6: K리그 | B6: 3월 18일 | C6: 수 | D6: 4 | E6: 대전 | F6: 홈 | G6: 1 | H6: 3 | I6: 패 | M6: 무고사 | Q6: 이주용 | U6: 6360 | V6: 김종혁 | X6: 페리어 | Y6: =Z6+AA6 -> 29 | Z6: =COUNTIF('출전기록 (26)'!C$2:M$39,'2026 토탈'!X6) -> 16 | AA6: =COUNTIF('출전기록 (26)'!N$2:S$39,'2026 토탈'!X6) -> 13 | AB6: =COUNTIF($M$3:$P$40,$X6) -> 7 | AC6: =COUNTIF($Q$3:$T$40,$X6) -> 2 | AD6: =AB6+AC6 -> 9 | AE6: =AF6+AG6 -> 29 | AF6: =COUNTIF('출전기록 (26)'!W$2:AG$7,'2026 토탈'!X6)+Z6 -> 16 | AG6: =COUNTIF('출전기록 (26)'!AH$2:AM$7,'2026 토탈'!X6)+AA6 -> 13 | AH6: =COUNTIF($M$3:$P$41,$X6) -> 7 | AI6: =COUNTIF($Q$3:$T$41,$X6) -> 2 | AJ6: =AH6+AI6 -> 9 | AM6: 팀명 | AN6: 경기 | AO6: 승 | AP6: 무 | AQ6: 패 | AR6: 승점 | AS6: 승률 | AT6: 득점 | AU6: 실점 | AV6: 득실 | BA6: 김종혁 | BB6: =SUM(BC6:BE6) -> 5 | BC6: =COUNTIFS($V$3:$V$40,$BA6,$I$3:$I$40,BC$2) -> 2 | BD6: =COUNTIFS($V$3:$V$40,$BA6,$I$3:$I$40,BD$2) -> 1 | BE6: =COUNTIFS($V$3:$V$40,$BA6,$I$3:$I$40,BE$2) -> 2 | BF6: =BC6*3+BD6 -> 7 | BG6: =IFERROR(BC6/BB6,0) -> 0.4 | BI6: 4 | BJ6: 전북 | BK6: 33 | BL6: 12 | BM6: 12 | BN6: 9 | BO6: 43 | BP6: 33 | BQ6: =BO6-BP6 -> 10 | BR6: 48
A7: K리그 | B7: 3월 22일 | C7: 일 | D7: 5 | E7: 안양 | F7: 원정 | G7: 1 | H7: 0 | I7: 승 | M7: 무고사 | V7: 채상협 | X7: 제르소 | Y7: =Z7+AA7 -> 33 | Z7: =COUNTIF('출전기록 (26)'!C$2:M$39,'2026 토탈'!X7) -> 19 | AA7: =COUNTIF('출전기록 (26)'!N$2:S$39,'2026 토탈'!X7) -> 14 | AB7: =COUNTIF($M$3:$P$40,$X7) -> 4 | AC7: =COUNTIF($Q$3:$T$40,$X7) -> 0 | AD7: =AB7+AC7 -> 4 | AE7: =AF7+AG7 -> 33 | AF7: =COUNTIF('출전기록 (26)'!W$2:AG$7,'2026 토탈'!X7)+Z7 -> 19 | AG7: =COUNTIF('출전기록 (26)'!AH$2:AM$7,'2026 토탈'!X7)+AA7 -> 14 | AH7: =COUNTIF($M$3:$P$41,$X7) -> 4 | AI7: =COUNTIF($Q$3:$T$41,$X7) -> 0 | AJ7: =AH7+AI7 -> 4 | AL7: K리그 | AM7: 전북 | AN7: =SUM(AO7:AQ7) -> 3 | AO7: =COUNTIFS(A:A,AL7,E:E,AM7,I:I,"승") -> 2 | AP7: =COUNTIFS(A:A,AL7,E:E,AM7,I:I,"무") -> 1 | AQ7: =COUNTIFS(A:A,AL7,E:E,AM7,I:I,"패") -> 0 | AR7: =AO7*3+AP7 -> 7 | AS7: =AO7/AN7 -> 0.66666667 | AT7: =SUMIF(E:E,AM7,G:G) -> 4 | AU7: =SUMIF(E:E,AM7,H:H) -> 2 | AV7: =AT7-AU7 -> 2 | BA7: 채상협 | BB7: =SUM(BC7:BE7) -> 1 | BC7: =COUNTIFS($V$3:$V$40,$BA7,$I$3:$I$40,BC$2) -> 1 | BD7: =COUNTIFS($V$3:$V$40,$BA7,$I$3:$I$40,BD$2) -> 0 | BE7: =COUNTIFS($V$3:$V$40,$BA7,$I$3:$I$40,BE$2) -> 0 | BF7: =BC7*3+BD7 -> 3 | BG7: =IFERROR(BC7/BB7,0) -> 1 | BI7: 5 | BJ7: 강원 | BK7: 33 | BL7: 11 | BM7: 15 | BN7: 7 | BO7: 40 | BP7: 30 | BQ7: =BO7-BP7 -> 10 | BR7: 48
A8: K리그 | B8: 4월 5일 | C8: 일 | D8: 6 | E8: 김천 | F8: 홈 | G8: 2 | H8: 1 | I8: 승 | M8: 무고사 | N8: 무고사 | Q8: 이명주 | U8: 8239 | V8: 최철준 | X8: 서재민 | Y8: =Z8+AA8 -> 32 | Z8: =COUNTIF('출전기록 (26)'!C$2:M$39,'2026 토탈'!X8) -> 30 | AA8: =COUNTIF('출전기록 (26)'!N$2:S$39,'2026 토탈'!X8) -> 2 | AB8: =COUNTIF($M$3:$P$40,$X8) -> 1 | AC8: =COUNTIF($Q$3:$T$40,$X8) -> 1 | AD8: =AB8+AC8 -> 2 | AE8: =AF8+AG8 -> 32 | AF8: =COUNTIF('출전기록 (26)'!W$2:AG$7,'2026 토탈'!X8)+Z8 -> 30 | AG8: =COUNTIF('출전기록 (26)'!AH$2:AM$7,'2026 토탈'!X8)+AA8 -> 2 | AH8: =COUNTIF($M$3:$P$41,$X8) -> 1 | AI8: =COUNTIF($Q$3:$T$41,$X8) -> 1 | AJ8: =AH8+AI8 -> 2 | AL8: K리그 | AM8: 대전 | AN8: =SUM(AO8:AQ8) -> 3 | AO8: =COUNTIFS(A:A,AL8,E:E,AM8,I:I,"승") -> 0 | AP8: =COUNTIFS(A:A,AL8,E:E,AM8,I:I,"무") -> 2 | AQ8: =COUNTIFS(A:A,AL8,E:E,AM8,I:I,"패") -> 1 | AR8: =AO8*3+AP8 -> 2 | AS8: =AO8/AN8 -> 0 | AT8: =SUMIF(E:E,AM8,G:G) -> 2 | AU8: =SUMIF(E:E,AM8,H:H) -> 4 | AV8: =AT8-AU8 -> -2 | BA8: 최철준 | BB8: =SUM(BC8:BE8) -> 3 | BC8: =COUNTIFS($V$3:$V$40,$BA8,$I$3:$I$40,BC$2) -> 1 | BD8: =COUNTIFS($V$3:$V$40,$BA8,$I$3:$I$40,BD$2) -> 1 | BE8: =COUNTIFS($V$3:$V$40,$BA8,$I$3:$I$40,BE$2) -> 1 | BF8: =BC8*3+BD8 -> 4 | BG8: =IFERROR(BC8/BB8,0) -> 0.33333333 | BI8: 6 | BJ8: 인천 | BK8: 33 | BL8: 12 | BM8: 10 | BN8: 11 | BO8: 43 | BP8: 35 | BQ8: =BO8-BP8 -> 8 | BR8: 46
A9: K리그 | B9: 4월 11일 | C9: 토 | D9: 7 | E9: 울산 | F9: 홈 | G9: 1 | H9: 2 | I9: 패 | M9: 무고사 | Q9: 서재민 | U9: 11358 | V9: 송민석 | X9: 이명주 | Y9: =Z9+AA9 -> 31 | Z9: =COUNTIF('출전기록 (26)'!C$2:M$39,'2026 토탈'!X9) -> 27 | AA9: =COUNTIF('출전기록 (26)'!N$2:S$39,'2026 토탈'!X9) -> 4 | AB9: =COUNTIF($M$3:$P$40,$X9) -> 2 | AC9: =COUNTIF($Q$3:$T$40,$X9) -> 3 | AD9: =AB9+AC9 -> 5 | AE9: =AF9+AG9 -> 31 | AF9: =COUNTIF('출전기록 (26)'!W$2:AG$7,'2026 토탈'!X9)+Z9 -> 27 | AG9: =COUNTIF('출전기록 (26)'!AH$2:AM$7,'2026 토탈'!X9)+AA9 -> 4 | AH9: =COUNTIF($M$3:$P$41,$X9) -> 2 | AI9: =COUNTIF($Q$3:$T$41,$X9) -> 3 | AJ9: =AH9+AI9 -> 5 | AL9: K리그 | AM9: 김천 | AN9: =SUM(AO9:AQ9) -> 3 | AO9: =COUNTIFS(A:A,AL9,E:E,AM9,I:I,"승") -> 2 | AP9: =COUNTIFS(A:A,AL9,E:E,AM9,I:I,"무") -> 1 | AQ9: =COUNTIFS(A:A,AL9,E:E,AM9,I:I,"패") -> 0 | AR9: =AO9*3+AP9 -> 7 | AS9: =AO9/AN9 -> 0.66666667 | AT9: =SUMIF(E:E,AM9,G:G) -> 6 | AU9: =SUMIF(E:E,AM9,H:H) -> 2 | AV9: =AT9-AU9 -> 4 | BA9: 송민석 | BB9: =SUM(BC9:BE9) -> 3 | BC9: =COUNTIFS($V$3:$V$40,$BA9,$I$3:$I$40,BC$2) -> 1 | BD9: =COUNTIFS($V$3:$V$40,$BA9,$I$3:$I$40,BD$2) -> 1 | BE9: =COUNTIFS($V$3:$V$40,$BA9,$I$3:$I$40,BE$2) -> 1 | BF9: =BC9*3+BD9 -> 4 | BG9: =IFERROR(BC9/BB9,0) -> 0.33333333 | BI9: 7 | BJ9: 제주 | BK9: 33 | BL9: 12 | BM9: 10 | BN9: 11 | BO9: 39 | BP9: 37 | BQ9: =BO9-BP9 -> 2 | BR9: 46
A10: K리그 | B10: 4월 18일 | C10: 토 | D10: 8 | E10: 부천 | F10: 원정 | G10: 2 | H10: 2 | I10: 무 | M10: 페리어 | N10: 제르소 | Q10: 김명순 | V10: 신용준 | X10: 오후성 | Y10: =Z10+AA10 -> 9 | Z10: =COUNTIF('출전기록 (26)'!C$2:M$39,'2026 토탈'!X10) -> 7 | AA10: =COUNTIF('출전기록 (26)'!N$2:S$39,'2026 토탈'!X10) -> 2 | AB10: =COUNTIF($M$3:$P$40,$X10) -> 1 | AC10: =COUNTIF($Q$3:$T$40,$X10) -> 0 | AD10: =AB10+AC10 -> 1 | AE10: =AF10+AG10 -> 9 | AF10: =COUNTIF('출전기록 (26)'!W$2:AG$7,'2026 토탈'!X10)+Z10 -> 7 | AG10: =COUNTIF('출전기록 (26)'!AH$2:AM$7,'2026 토탈'!X10)+AA10 -> 2 | AH10: =COUNTIF($M$3:$P$41,$X10) -> 1 | AI10: =COUNTIF($Q$3:$T$41,$X10) -> 0 | AJ10: =AH10+AI10 -> 1 | AL10: K리그 | AM10: 서울 | AN10: =SUM(AO10:AQ10) -> 3 | AO10: =COUNTIFS(A:A,AL10,E:E,AM10,I:I,"승") -> 0 | AP10: =COUNTIFS(A:A,AL10,E:E,AM10,I:I,"무") -> 0 | AQ10: =COUNTIFS(A:A,AL10,E:E,AM10,I:I,"패") -> 3 | AR10: =AO10*3+AP10 -> 0 | AS10: =AO10/AN10 -> 0 | AT10: =SUMIF(E:E,AM10,G:G) -> 1 | AU10: =SUMIF(E:E,AM10,H:H) -> 4 | AV10: =AT10-AU10 -> -3 | BA10: 신용준 | BB10: =SUM(BC10:BE10) -> 4 | BC10: =COUNTIFS($V$3:$V$40,$BA10,$I$3:$I$40,BC$2) -> 2 | BD10: =COUNTIFS($V$3:$V$40,$BA10,$I$3:$I$40,BD$2) -> 1 | BE10: =COUNTIFS($V$3:$V$40,$BA10,$I$3:$I$40,BE$2) -> 1 | BF10: =BC10*3+BD10 -> 7 | BG10: =IFERROR(BC10/BB10,0) -> 0.5 | BI10: 8 | BJ10: 안양 | BK10: 33 | BL10: 10 | BM10: 13 | BN10: 10 | BO10: 40 | BP10: 48 | BQ10: =BO10-BP10 -> -8 | BR10: 43
A11: K리그 | B11: 4월 21일 | C11: 화 | D11: 9 | E11: 전북 | F11: 원정 | G11: 2 | H11: 1 | I11: 승 | M11: 이명주 | N11: 이동률 | Q11: 최승구 | V11: 김종혁 | X11: 이청용 | Y11: =Z11+AA11 -> 33 | Z11: =COUNTIF('출전기록 (26)'!C$2:M$39,'2026 토탈'!X11) -> 22 | AA11: =COUNTIF('출전기록 (26)'!N$2:S$39,'2026 토탈'!X11) -> 11 | AB11: =COUNTIF($M$3:$P$40,$X11) -> 3 | AC11: =COUNTIF($Q$3:$T$40,$X11) -> 2 | AD11: =AB11+AC11 -> 5 | AE11: =AF11+AG11 -> 33 | AF11: =COUNTIF('출전기록 (26)'!W$2:AG$7,'2026 토탈'!X11)+Z11 -> 22 | AG11: =COUNTIF('출전기록 (26)'!AH$2:AM$7,'2026 토탈'!X11)+AA11 -> 11 | AH11: =COUNTIF($M$3:$P$41,$X11) -> 3 | AI11: =COUNTIF($Q$3:$T$41,$X11) -> 2 | AJ11: =AH11+AI11 -> 5 | AL11: K리그 | AM11: 포항 | AN11: =SUM(AO11:AQ11) -> 3 | AO11: =COUNTIFS(A:A,AL11,E:E,AM11,I:I,"승") -> 1 | AP11: =COUNTIFS(A:A,AL11,E:E,AM11,I:I,"무") -> 1 | AQ11: =COUNTIFS(A:A,AL11,E:E,AM11,I:I,"패") -> 1 | AR11: =AO11*3+AP11 -> 4 | AS11: =AO11/AN11 -> 0.33333333 | AT11: =SUMIF(E:E,AM11,G:G) -> 4 | AU11: =SUMIF(E:E,AM11,H:H) -> 2 | AV11: =AT11-AU11 -> 2 | BA11: 고형진 | BB11: =SUM(BC11:BE11) -> 3 | BC11: =COUNTIFS($V$3:$V$40,$BA11,$I$3:$I$40,BC$2) -> 1 | BD11: =COUNTIFS($V$3:$V$40,$BA11,$I$3:$I$40,BD$2) -> 0 | BE11: =COUNTIFS($V$3:$V$40,$BA11,$I$3:$I$40,BE$2) -> 2 | BF11: =BC11*3+BD11 -> 3 | BG11: =IFERROR(BC11/BB11,0) -> 0.33333333 | BI11: 9 | BJ11: 포항 | BK11: 33 | BL11: 11 | BM11: 9 | BN11: 13 | BO11: 30 | BP11: 39 | BQ11: =BO11-BP11 -> -9 | BR11: 42
A12: K리그 | B12: 4월 25일 | C12: 토 | D12: 10 | E12: 제주 | F12: 홈 | G12: 1 | H12: 0 | I12: 승 | M12: 페리어 | Q12: 이동률 | U12: 8371 | V12: 최현재 | X12: 정치인 | Y12: =Z12+AA12 -> 19 | Z12: =COUNTIF('출전기록 (26)'!C$2:M$39,'2026 토탈'!X12) -> 7 | AA12: =COUNTIF('출전기록 (26)'!N$2:S$39,'2026 토탈'!X12) -> 12 | AB12: =COUNTIF($M$3:$P$40,$X12) -> 0 | AC12: =COUNTIF($Q$3:$T$40,$X12) -> 1 | AD12: =AB12+AC12 -> 1 | AE12: =AF12+AG12 -> 19 | AF12: =COUNTIF('출전기록 (26)'!W$2:AG$7,'2026 토탈'!X12)+Z12 -> 7 | AG12: =COUNTIF('출전기록 (26)'!AH$2:AM$7,'2026 토탈'!X12)+AA12 -> 12 | AH12: =COUNTIF($M$3:$P$41,$X12) -> 0 | AI12: =COUNTIF($Q$3:$T$41,$X12) -> 1 | AJ12: =AH12+AI12 -> 1 | AL12: K리그 | AM12: 강원 | AN12: =SUM(AO12:AQ12) -> 3 | AO12: =COUNTIFS(A:A,AL12,E:E,AM12,I:I,"승") -> 0 | AP12: =COUNTIFS(A:A,AL12,E:E,AM12,I:I,"무") -> 2 | AQ12: =COUNTIFS(A:A,AL12,E:E,AM12,I:I,"패") -> 1 | AR12: =AO12*3+AP12 -> 2 | AT12: =SUMIF(E:E,AM12,G:G) -> 1 | AU12: =SUMIF(E:E,AM12,H:H) -> 2 | AV12: =AT12-AU12 -> -1 | BA12: 김우성 | BB12: =SUM(BC12:BE12) -> 2 | BC12: =COUNTIFS($V$3:$V$40,$BA12,$I$3:$I$40,BC$2) -> 2 | BD12: =COUNTIFS($V$3:$V$40,$BA12,$I$3:$I$40,BD$2) -> 0 | BE12: =COUNTIFS($V$3:$V$40,$BA12,$I$3:$I$40,BE$2) -> 0 | BF12: =BC12*3+BD12 -> 6 | BG12: =IFERROR(BC12/BB12,0) -> 1 | BI12: 10 | BJ12: 김천 | BK12: 33 | BL12: 5 | BM12: 19 | BN12: 9 | BO12: 33 | BP12: 41 | BQ12: =BO12-BP12 -> -8 | BR12: 34
A13: K리그 | B13: 5월 2일 | C13: 토 | D13: 11 | E13: 강원 | F13: 홈 | G13: 0 | H13: 1 | I13: 패 | U13: 11404 | V13: 고형진 | X13: 이케르 | Y13: =Z13+AA13 -> 9 | Z13: =COUNTIF('출전기록 (26)'!C$2:M$39,'2026 토탈'!X13) -> 2 | AA13: =COUNTIF('출전기록 (26)'!N$2:S$39,'2026 토탈'!X13) -> 7 | AB13: =COUNTIF($M$3:$P$40,$X13) -> 0 | AC13: =COUNTIF($Q$3:$T$40,$X13) -> 0 | AD13: =AB13+AC13 -> 0 | AE13: =AF13+AG13 -> 9 | AF13: =COUNTIF('출전기록 (26)'!W$2:AG$7,'2026 토탈'!X13)+Z13 -> 2 | AG13: =COUNTIF('출전기록 (26)'!AH$2:AM$7,'2026 토탈'!X13)+AA13 -> 7 | AH13: =COUNTIF($M$3:$P$41,$X13) -> 0 | AI13: =COUNTIF($Q$3:$T$41,$X13) -> 0 | AJ13: =AH13+AI13 -> 0 | AL13: K리그 | AM13: 광주 | AN13: =SUM(AO13:AQ13) -> 3 | AO13: =COUNTIFS(A:A,AL13,E:E,AM13,I:I,"승") -> 2 | AP13: =COUNTIFS(A:A,AL13,E:E,AM13,I:I,"무") -> 0 | AQ13: =COUNTIFS(A:A,AL13,E:E,AM13,I:I,"패") -> 1 | AR13: =AO13*3+AP13 -> 6 | AS13: =AO13/AN13 -> 0.66666667 | AT13: =SUMIF(E:E,AM13,G:G) -> 7 | AU13: =SUMIF(E:E,AM13,H:H) -> 3 | AV13: =AT13-AU13 -> 4 | BA13: 박병진 | BB13: =SUM(BC13:BE13) -> 2 | BC13: =COUNTIFS($V$3:$V$40,$BA13,$I$3:$I$40,BC$2) -> 1 | BD13: =COUNTIFS($V$3:$V$40,$BA13,$I$3:$I$40,BD$2) -> 1 | BE13: =COUNTIFS($V$3:$V$40,$BA13,$I$3:$I$40,BE$2) -> 0 | BF13: =BC13*3+BD13 -> 4 | BG13: =IFERROR(BC13/BB13,0) -> 0.5 | BI13: 11 | BJ13: 부천 | BK13: 33 | BL13: 7 | BM13: 11 | BN13: 15 | BO13: 32 | BP13: 47 | BQ13: =BO13-BP13 -> -15 | BR13: 32
A14: K리그 | B14: 5월 5일 | C14: 화 | D14: 12 | E14: 대전 | F14: 원정 | G14: 0 | H14: 0 | I14: 무 | V14: 김종혁 | X14: 김성민 | Y14: =Z14+AA14 -> 19 | Z14: =COUNTIF('출전기록 (26)'!C$2:M$39,'2026 토탈'!X14) -> 8 | AA14: =COUNTIF('출전기록 (26)'!N$2:S$39,'2026 토탈'!X14) -> 11 | AB14: =COUNTIF($M$3:$P$40,$X14) -> 0 | AC14: =COUNTIF($Q$3:$T$40,$X14) -> 1 | AD14: =AB14+AC14 -> 1 | AE14: =AF14+AG14 -> 19 | AF14: =COUNTIF('출전기록 (26)'!W$2:AG$7,'2026 토탈'!X14)+Z14 -> 8 | AG14: =COUNTIF('출전기록 (26)'!AH$2:AM$7,'2026 토탈'!X14)+AA14 -> 11 | AH14: =COUNTIF($M$3:$P$41,$X14) -> 0 | AI14: =COUNTIF($Q$3:$T$41,$X14) -> 1 | AJ14: =AH14+AI14 -> 1 | AL14: K리그 | AM14: 안양 | AN14: =SUM(AO14:AQ14) -> 3 | AO14: =COUNTIFS(A:A,AL14,E:E,AM14,I:I,"승") -> 1 | AP14: =COUNTIFS(A:A,AL14,E:E,AM14,I:I,"무") -> 0 | AQ14: =COUNTIFS(A:A,AL14,E:E,AM14,I:I,"패") -> 2 | AR14: =AO14*3+AP14 -> 3 | AS14: =AO14/AN14 -> 0.33333333 | AT14: =SUMIF(E:E,AM14,G:G) -> 2 | AU14: =SUMIF(E:E,AM14,H:H) -> 3 | AV14: =AT14-AU14 -> -1 | BA14: 김대용 | BB14: =SUM(BC14:BE14) -> 2 | BC14: =COUNTIFS($V$3:$V$40,$BA14,$I$3:$I$40,BC$2) -> 0 | BD14: =COUNTIFS($V$3:$V$40,$BA14,$I$3:$I$40,BD$2) -> 2 | BE14: =COUNTIFS($V$3:$V$40,$BA14,$I$3:$I$40,BE$2) -> 0 | BF14: =BC14*3+BD14 -> 2 | BG14: =IFERROR(BC14/BB14,0) -> 0 | BI14: 12 | BJ14: 광주 | BK14: 33 | BL14: 3 | BM14: 12 | BN14: 18 | BO14: 30 | BP14: 69 | BQ14: =BO14-BP14 -> -39 | BR14: 21
A15: K리그 | B15: 5월 9일 | C15: 토 | D15: 13 | E15: 김천 | F15: 원정 | G15: 3 | H15: 0 | I15: 승 | M15: 이비자 | N15: 이동률 | O15: 페리어 | Q15: 이명주 | V15: 신용준 | X15: 정원진 | Y15: =Z15+AA15 -> 1 | Z15: =COUNTIF('출전기록 (26)'!C$2:M$39,'2026 토탈'!X15) -> 1 | AA15: =COUNTIF('출전기록 (26)'!N$2:S$39,'2026 토탈'!X15) -> 0 | AB15: =COUNTIF($M$3:$P$40,$X15) -> 0 | AC15: =COUNTIF($Q$3:$T$40,$X15) -> 0 | AD15: =AB15+AC15 -> 0 | AE15: =AF15+AG15 -> 1 | AF15: =COUNTIF('출전기록 (26)'!W$2:AG$7,'2026 토탈'!X15)+Z15 -> 1 | AG15: =COUNTIF('출전기록 (26)'!AH$2:AM$7,'2026 토탈'!X15)+AA15 -> 0 | AH15: =COUNTIF($M$3:$P$41,$X15) -> 0 | AI15: =COUNTIF($Q$3:$T$41,$X15) -> 0 | AJ15: =AH15+AI15 -> 0 | AL15: K리그 | AM15: 울산 | AN15: =SUM(AO15:AQ15) -> 3 | AO15: =COUNTIFS(A:A,AL15,E:E,AM15,I:I,"승") -> 1 | AP15: =COUNTIFS(A:A,AL15,E:E,AM15,I:I,"무") -> 0 | AQ15: =COUNTIFS(A:A,AL15,E:E,AM15,I:I,"패") -> 2 | AR15: =AO15*3+AP15 -> 3 | AS15: =AO15/AN15 -> 0.33333333 | AT15: =SUMIF(E:E,AM15,G:G) -> 4 | AU15: =SUMIF(E:E,AM15,H:H) -> 5 | AV15: =AT15-AU15 -> -1 | BA15: 총합 | BB15: =SUM(BB3:BB14) -> 33 | BC15: =SUM(BC3:BC14) -> 12 | BD15: =SUM(BD3:BD14) -> 10 | BE15: =SUM(BE3:BE14) -> 11 | BF15: =SUM(BF3:BF14) -> 46 | BG15: =IFERROR(BC15/BB15,0) -> 0.36363636 | BI15: 출처: soccer365 / K리그 공식
A16: K리그 | B16: 5월 12일 | C16: 화 | D16: 14 | E16: 포항 | F16: 홈 | G16: 0 | H16: 1 | I16: 패 | U16: 6620 | V16: 설태환 | X16: 백민규 | Y16: =Z16+AA16 -> 1 | Z16: =COUNTIF('출전기록 (26)'!C$2:M$39,'2026 토탈'!X16) -> 0 | AA16: =COUNTIF('출전기록 (26)'!N$2:S$39,'2026 토탈'!X16) -> 1 | AB16: =COUNTIF($M$3:$P$40,$X16) -> 0 | AC16: =COUNTIF($Q$3:$T$40,$X16) -> 0 | AD16: =AB16+AC16 -> 0 | AE16: =AF16+AG16 -> 1 | AF16: =COUNTIF('출전기록 (26)'!W$2:AG$7,'2026 토탈'!X16)+Z16 -> 0 | AG16: =COUNTIF('출전기록 (26)'!AH$2:AM$7,'2026 토탈'!X16)+AA16 -> 1 | AH16: =COUNTIF($M$3:$P$41,$X16) -> 0 | AI16: =COUNTIF($Q$3:$T$41,$X16) -> 0 | AJ16: =AH16+AI16 -> 0 | AL16: K리그 | AM16: 제주 | AN16: =SUM(AO16:AQ16) -> 3 | AO16: =COUNTIFS(A:A,AL16,E:E,AM16,I:I,"승") -> 2 | AP16: =COUNTIFS(A:A,AL16,E:E,AM16,I:I,"무") -> 1 | AQ16: =COUNTIFS(A:A,AL16,E:E,AM16,I:I,"패") -> 0 | AR16: =AO16*3+AP16 -> 7 | AS16: =AO16/AN16 -> 0.66666667 | AT16: =SUMIF(E:E,AM16,G:G) -> 7 | AU16: =SUMIF(E:E,AM16,H:H) -> 4 | AV16: =AT16-AU16 -> 3
A17: K리그 | B17: 5월 16일 | C17: 토 | D17: 15 | E17: 광주 | F17: 홈 | G17: 4 | H17: 0 | I17: 승 | M17: 이비자 | N17: 페리어 | O17: 제르소 | P17: 이청용 | Q17: 이주용 | R17: 이청용 | S17: 이동률 | U17: 11128 | V17: 김우성 | X17: 문지환 | Y17: =Z17+AA17 -> 1 | Z17: =COUNTIF('출전기록 (26)'!C$2:M$39,'2026 토탈'!X17) -> 0 | AA17: =COUNTIF('출전기록 (26)'!N$2:S$39,'2026 토탈'!X17) -> 1 | AB17: =COUNTIF($M$3:$P$40,$X17) -> 0 | AC17: =COUNTIF($Q$3:$T$40,$X17) -> 0 | AD17: =AB17+AC17 -> 0 | AE17: =AF17+AG17 -> 1 | AF17: =COUNTIF('출전기록 (26)'!W$2:AG$7,'2026 토탈'!X17)+Z17 -> 0 | AG17: =COUNTIF('출전기록 (26)'!AH$2:AM$7,'2026 토탈'!X17)+AA17 -> 1 | AH17: =COUNTIF($M$3:$P$41,$X17) -> 0 | AI17: =COUNTIF($Q$3:$T$41,$X17) -> 0 | AJ17: =AH17+AI17 -> 0 | AL17: K리그 | AM17: 부천 | AN17: =SUM(AO17:AQ17) -> 3 | AO17: =COUNTIFS(A:A,AL17,E:E,AM17,I:I,"승") -> 1 | AP17: =COUNTIFS(A:A,AL17,E:E,AM17,I:I,"무") -> 2 | AQ17: =COUNTIFS(A:A,AL17,E:E,AM17,I:I,"패") -> 0 | AR17: =AO17*3+AP17 -> 5 | AS17: =AO17/AN17 -> 0.33333333 | AT17: =SUMIF(E:E,AM17,G:G) -> 5 | AU17: =SUMIF(E:E,AM17,H:H) -> 4 | AV17: =AT17-AU17 -> 1
A18: K리그 | B18: 7월 5일 | C18: 일 | D18: 16 | E18: 서울 | F18: 원정 | G18: 0 | H18: 1 | I18: 패 | V18: 신용준 | X18: 김영환 | Y18: =Z18+AA18 -> 6 | Z18: =COUNTIF('출전기록 (26)'!C$2:M$39,'2026 토탈'!X18) -> 2 | AA18: =COUNTIF('출전기록 (26)'!N$2:S$39,'2026 토탈'!X18) -> 4 | AB18: =COUNTIF($M$3:$P$40,$X18) -> 0 | AC18: =COUNTIF($Q$3:$T$40,$X18) -> 1 | AD18: =AB18+AC18 -> 1 | AE18: =AF18+AG18 -> 6 | AF18: =COUNTIF('출전기록 (26)'!W$2:AG$7,'2026 토탈'!X18)+Z18 -> 2 | AG18: =COUNTIF('출전기록 (26)'!AH$2:AM$7,'2026 토탈'!X18)+AA18 -> 4 | AH18: =COUNTIF($M$3:$P$41,$X18) -> 0 | AI18: =COUNTIF($Q$3:$T$41,$X18) -> 1 | AJ18: =AH18+AI18 -> 1
A19: K리그 | B19: 7월 12일 | C19: 일 | D19: 17 | E19: 안양 | F19: 홈 | G19: 0 | H19: 1 | I19: 패 | U19: 10616 | V19: 최철준 | X19: 오준엽 | Y19: =Z19+AA19 -> 0 | Z19: =COUNTIF('출전기록 (26)'!C$2:M$39,'2026 토탈'!X19) -> 0 | AA19: =COUNTIF('출전기록 (26)'!N$2:S$39,'2026 토탈'!X19) -> 0 | AB19: =COUNTIF($M$3:$P$40,$X19) -> 0 | AC19: =COUNTIF($Q$3:$T$40,$X19) -> 0 | AD19: =AB19+AC19 -> 0 | AE19: =AF19+AG19 -> 0 | AF19: =COUNTIF('출전기록 (26)'!W$2:AG$7,'2026 토탈'!X19)+Z19 -> 0 | AG19: =COUNTIF('출전기록 (26)'!AH$2:AM$7,'2026 토탈'!X19)+AA19 -> 0 | AH19: =COUNTIF($M$3:$P$41,$X19) -> 0 | AI19: =COUNTIF($Q$3:$T$41,$X19) -> 0 | AJ19: =AH19+AI19 -> 0
A20: K리그 | B20: 7월 18일 | C20: 토 | D20: 18 | E20: 전북 | F20: 홈 | G20: 1 | H20: 0 | I20: 승 | M20: 제르소 | U20: 12984 | V20: 박병진 | X20: 박경섭 | Y20: =Z20+AA20 -> 14 | Z20: =COUNTIF('출전기록 (26)'!C$2:M$39,'2026 토탈'!X20) -> 10 | AA20: =COUNTIF('출전기록 (26)'!N$2:S$39,'2026 토탈'!X20) -> 4 | AB20: =COUNTIF($M$3:$P$40,$X20) -> 0 | AC20: =COUNTIF($Q$3:$T$40,$X20) -> 0 | AD20: =AB20+AC20 -> 0 | AE20: =AF20+AG20 -> 14 | AF20: =COUNTIF('출전기록 (26)'!W$2:AG$7,'2026 토탈'!X20)+Z20 -> 10 | AG20: =COUNTIF('출전기록 (26)'!AH$2:AM$7,'2026 토탈'!X20)+AA20 -> 4 | AH20: =COUNTIF($M$3:$P$41,$X20) -> 0 | AI20: =COUNTIF($Q$3:$T$41,$X20) -> 0 | AJ20: =AH20+AI20 -> 0
A21: K리그 | B21: 7월 21일 | C21: 화 | D21: 19 | E21: 울산 | F21: 원정 | G21: 2 | H21: 1 | I21: 승 | M21: 페리어 | N21: 무고사 | Q21: 김성민 | V21: 송민석 | X21: 김건희 | Y21: =Z21+AA21 -> 23 | Z21: =COUNTIF('출전기록 (26)'!C$2:M$39,'2026 토탈'!X21) -> 22 | AA21: =COUNTIF('출전기록 (26)'!N$2:S$39,'2026 토탈'!X21) -> 1 | AB21: =COUNTIF($M$3:$P$40,$X21) -> 2 | AC21: =COUNTIF($Q$3:$T$40,$X21) -> 0 | AD21: =AB21+AC21 -> 2 | AE21: =AF21+AG21 -> 23 | AF21: =COUNTIF('출전기록 (26)'!W$2:AG$7,'2026 토탈'!X21)+Z21 -> 22 | AG21: =COUNTIF('출전기록 (26)'!AH$2:AM$7,'2026 토탈'!X21)+AA21 -> 1 | AH21: =COUNTIF($M$3:$P$41,$X21) -> 2 | AI21: =COUNTIF($Q$3:$T$41,$X21) -> 0 | AJ21: =AH21+AI21 -> 2
A22: K리그 | B22: 7월 26일 | C22: 일 | D22: 20 | E22: 부천 | F22: 홈 | G22: 1 | H22: 1 | I22: 무 | M22: 페리어 | Q22: 정치인 | U22: 8623 | V22: 최철준 | X22: 이비자 | Y22: =Z22+AA22 -> 31 | Z22: =COUNTIF('출전기록 (26)'!C$2:M$39,'2026 토탈'!X22) -> 31 | AA22: =COUNTIF('출전기록 (26)'!N$2:S$39,'2026 토탈'!X22) -> 0 | AB22: =COUNTIF($M$3:$P$40,$X22) -> 3 | AC22: =COUNTIF($Q$3:$T$40,$X22) -> 1 | AD22: =AB22+AC22 -> 4 | AE22: =AF22+AG22 -> 31 | AF22: =COUNTIF('출전기록 (26)'!W$2:AG$7,'2026 토탈'!X22)+Z22 -> 31 | AG22: =COUNTIF('출전기록 (26)'!AH$2:AM$7,'2026 토탈'!X22)+AA22 -> 0 | AH22: =COUNTIF($M$3:$P$41,$X22) -> 3 | AI22: =COUNTIF($Q$3:$T$41,$X22) -> 1 | AJ22: =AH22+AI22 -> 4
A23: K리그 | B23: 8월 2일 | C23: 일 | D23: 21 | E23: 제주 | F23: 원정 | G23: 3 | H23: 3 | I23: 무 | M23: 김건희 | N23: 김건희 | O23: 이주용 | Q23: 이주용 | R23: 이주용 | S23: 이청용 | V23: 김대용 | X23: 김명순 | Y23: =Z23+AA23 -> 30 | Z23: =COUNTIF('출전기록 (26)'!C$2:M$39,'2026 토탈'!X23) -> 30 | AA23: =COUNTIF('출전기록 (26)'!N$2:S$39,'2026 토탈'!X23) -> 0 | AB23: =COUNTIF($M$3:$P$40,$X23) -> 0 | AC23: =COUNTIF($Q$3:$T$40,$X23) -> 2 | AD23: =AB23+AC23 -> 2 | AE23: =AF23+AG23 -> 30 | AF23: =COUNTIF('출전기록 (26)'!W$2:AG$7,'2026 토탈'!X23)+Z23 -> 30 | AG23: =COUNTIF('출전기록 (26)'!AH$2:AM$7,'2026 토탈'!X23)+AA23 -> 0 | AH23: =COUNTIF($M$3:$P$41,$X23) -> 0 | AI23: =COUNTIF($Q$3:$T$41,$X23) -> 2 | AJ23: =AH23+AI23 -> 2
A24: K리그 | B24: 9월 27일 | C24: 일 | D24: 22 | E24: 강원 | F24: 원정 | G24: 0 | H24: 0 | I24: 무 | U24: 5274 | V24: 박병진 | X24: 이주용 | Y24: =Z24+AA24 -> 32 | Z24: =COUNTIF('출전기록 (26)'!C$2:M$39,'2026 토탈'!X24) -> 29 | AA24: =COUNTIF('출전기록 (26)'!N$2:S$39,'2026 토탈'!X24) -> 3 | AB24: =COUNTIF($M$3:$P$40,$X24) -> 1 | AC24: =COUNTIF($Q$3:$T$40,$X24) -> 4 | AD24: =AB24+AC24 -> 5 | AE24: =AF24+AG24 -> 32 | AF24: =COUNTIF('출전기록 (26)'!W$2:AG$7,'2026 토탈'!X24)+Z24 -> 29 | AG24: =COUNTIF('출전기록 (26)'!AH$2:AM$7,'2026 토탈'!X24)+AA24 -> 3 | AH24: =COUNTIF($M$3:$P$41,$X24) -> 1 | AI24: =COUNTIF($Q$3:$T$41,$X24) -> 4 | AJ24: =AH24+AI24 -> 5
A25: K리그 | B25: 8월 16일 | C25: 일 | D25: 23 | E25: 김천 | F25: 홈 | G25: 1 | H25: 1 | I25: 무 | M25: 무고사 | Q25: 페리어 | U25: 8013 | V25: 송민석 | X25: 최승구 | Y25: =Z25+AA25 -> 19 | Z25: =COUNTIF('출전기록 (26)'!C$2:M$39,'2026 토탈'!X25) -> 3 | AA25: =COUNTIF('출전기록 (26)'!N$2:S$39,'2026 토탈'!X25) -> 16 | AB25: =COUNTIF($M$3:$P$40,$X25) -> 0 | AC25: =COUNTIF($Q$3:$T$40,$X25) -> 1 | AD25: =AB25+AC25 -> 1 | AE25: =AF25+AG25 -> 19 | AF25: =COUNTIF('출전기록 (26)'!W$2:AG$7,'2026 토탈'!X25)+Z25 -> 3 | AG25: =COUNTIF('출전기록 (26)'!AH$2:AM$7,'2026 토탈'!X25)+AA25 -> 16 | AH25: =COUNTIF($M$3:$P$41,$X25) -> 0 | AI25: =COUNTIF($Q$3:$T$41,$X25) -> 1 | AJ25: =AH25+AI25 -> 1
A26: K리그 | B26: 8월 23일 | C26: 일 | D26: 24 | E26: 광주 | F26: 원정 | G26: 1 | H26: 0 | I26: 승 | M26: 무고사 | V26: 김종혁 | X26: 여승원 | Y26: =Z26+AA26 -> 5 | Z26: =COUNTIF('출전기록 (26)'!C$2:M$39,'2026 토탈'!X26) -> 2 | AA26: =COUNTIF('출전기록 (26)'!N$2:S$39,'2026 토탈'!X26) -> 3 | AB26: =COUNTIF($M$3:$P$40,$X26) -> 0 | AC26: =COUNTIF($Q$3:$T$40,$X26) -> 0 | AD26: =AB26+AC26 -> 0 | AE26: =AF26+AG26 -> 5 | AF26: =COUNTIF('출전기록 (26)'!W$2:AG$7,'2026 토탈'!X26)+Z26 -> 2 | AG26: =COUNTIF('출전기록 (26)'!AH$2:AM$7,'2026 토탈'!X26)+AA26 -> 3 | AH26: =COUNTIF($M$3:$P$41,$X26) -> 0 | AI26: =COUNTIF($Q$3:$T$41,$X26) -> 0 | AJ26: =AH26+AI26 -> 0
A27: K리그 | B27: 8월 26일 | C27: 수 | D27: 25 | E27: 안양 | F27: 원정 | G27: 1 | H27: 2 | I27: 패 | M27: 이동률 | Q27: 김영환 | V27: 이동준 | X27: 이상기 | Y27: =Z27+AA27 -> 3 | Z27: =COUNTIF('출전기록 (26)'!C$2:M$39,'2026 토탈'!X27) -> 2 | AA27: =COUNTIF('출전기록 (26)'!N$2:S$39,'2026 토탈'!X27) -> 1 | AB27: =COUNTIF($M$3:$P$40,$X27) -> 0 | AC27: =COUNTIF($Q$3:$T$40,$X27) -> 0 | AD27: =AB27+AC27 -> 0 | AE27: =AF27+AG27 -> 3 | AF27: =COUNTIF('출전기록 (26)'!W$2:AG$7,'2026 토탈'!X27)+Z27 -> 2 | AG27: =COUNTIF('출전기록 (26)'!AH$2:AM$7,'2026 토탈'!X27)+AA27 -> 1 | AH27: =COUNTIF($M$3:$P$41,$X27) -> 0 | AI27: =COUNTIF($Q$3:$T$41,$X27) -> 0 | AJ27: =AH27+AI27 -> 0
A28: K리그 | B28: 8월 30일 | C28: 일 | D28: 26 | E28: 전북 | F28: 홈 | G28: 1 | H28: 1 | I28: 무 | M28: 제르소 | U28: 11056 | V28: 김대용 | X28: 고정민 | Y28: =Z28+AA28 -> 0 | Z28: =COUNTIF('출전기록 (26)'!C$2:M$39,'2026 토탈'!X28) -> 0 | AA28: =COUNTIF('출전기록 (26)'!N$2:S$39,'2026 토탈'!X28) -> 0 | AB28: =COUNTIF($M$3:$P$40,$X28) -> 0 | AC28: =COUNTIF($Q$3:$T$40,$X28) -> 0 | AD28: =AB28+AC28 -> 0 | AE28: =AF28+AG28 -> 0 | AF28: =COUNTIF('출전기록 (26)'!W$2:AG$7,'2026 토탈'!X28)+Z28 -> 0 | AG28: =COUNTIF('출전기록 (26)'!AH$2:AM$7,'2026 토탈'!X28)+AA28 -> 0 | AH28: =COUNTIF($M$3:$P$41,$X28) -> 0 | AI28: =COUNTIF($Q$3:$T$41,$X28) -> 0 | AJ28: =AH28+AI28 -> 0
A29: K리그 | B29: 9월 5일 | C29: 토 | D29: 27 | E29: 서울 | F29: 원정 | G29: 0 | H29: 1 | I29: 패 | V29: 고형진 | X29: 이준섭 | Y29: =Z29+AA29 -> 0 | Z29: =COUNTIF('출전기록 (26)'!C$2:M$39,'2026 토탈'!X29) -> 0 | AA29: =COUNTIF('출전기록 (26)'!N$2:S$39,'2026 토탈'!X29) -> 0 | AB29: =COUNTIF($M$3:$P$40,$X29) -> 0 | AC29: =COUNTIF($Q$3:$T$40,$X29) -> 0 | AD29: =AB29+AC29 -> 0 | AE29: =AF29+AG29 -> 0 | AF29: =COUNTIF('출전기록 (26)'!W$2:AG$7,'2026 토탈'!X29)+Z29 -> 0 | AG29: =COUNTIF('출전기록 (26)'!AH$2:AM$7,'2026 토탈'!X29)+AA29 -> 0 | AH29: =COUNTIF($M$3:$P$41,$X29) -> 0 | AI29: =COUNTIF($Q$3:$T$41,$X29) -> 0 | AJ29: =AH29+AI29 -> 0
A30: K리그 | B30: 9월 8일 | C30: 화 | D30: 28 | E30: 부천 | F30: 홈 | G30: 2 | H30: 1 | I30: 승 | M30: 무고사 | N30: 이비자 | Q30: 레안드로 | R30: 이명주 | U30: 5794 | V30: 김우성 | X30: 정태욱 | Y30: =Z30+AA30 -> 0 | Z30: =COUNTIF('출전기록 (26)'!C$2:M$39,'2026 토탈'!X30) -> 0 | AA30: =COUNTIF('출전기록 (26)'!N$2:S$39,'2026 토탈'!X30) -> 0 | AB30: =COUNTIF($M$3:$P$40,$X30) -> 0 | AC30: =COUNTIF($Q$3:$T$40,$X30) -> 0 | AD30: =AB30+AC30 -> 0 | AE30: =AF30+AG30 -> 0 | AF30: =COUNTIF('출전기록 (26)'!W$2:AG$7,'2026 토탈'!X30)+Z30 -> 0 | AG30: =COUNTIF('출전기록 (26)'!AH$2:AM$7,'2026 토탈'!X30)+AA30 -> 0 | AH30: =COUNTIF($M$3:$P$41,$X30) -> 0 | AI30: =COUNTIF($Q$3:$T$41,$X30) -> 0 | AJ30: =AH30+AI30 -> 0
A31: K리그 | B31: 9월 12일 | C31: 토 | D31: 29 | E31: 울산 | F31: 원정 | G31: 1 | H31: 2 | I31: 패 | M31: 무고사 | V31: 김종혁 | X31: 강영훈 | Y31: =Z31+AA31 -> 0 | Z31: =COUNTIF('출전기록 (26)'!C$2:M$39,'2026 토탈'!X31) -> 0 | AA31: =COUNTIF('출전기록 (26)'!N$2:S$39,'2026 토탈'!X31) -> 0 | AB31: =COUNTIF($M$3:$P$40,$X31) -> 0 | AC31: =COUNTIF($Q$3:$T$40,$X31) -> 0 | AD31: =AB31+AC31 -> 0 | AE31: =AF31+AG31 -> 0 | AF31: =COUNTIF('출전기록 (26)'!W$2:AG$7,'2026 토탈'!X31)+Z31 -> 0 | AG31: =COUNTIF('출전기록 (26)'!AH$2:AM$7,'2026 토탈'!X31)+AA31 -> 0 | AH31: =COUNTIF($M$3:$P$41,$X31) -> 0 | AI31: =COUNTIF($Q$3:$T$41,$X31) -> 0 | AJ31: =AH31+AI31 -> 0
A32: K리그 | B32: 9월 20일 | C32: 일 | D32: 30 | E32: 대전 | F32: 홈 | G32: 1 | H32: 1 | I32: 무 | M32: 페리어 | U32: 9312 | V32: 최현재 | X32: 김연수 | Y32: =Z32+AA32 -> 3 | Z32: =COUNTIF('출전기록 (26)'!C$2:M$39,'2026 토탈'!X32) -> 3 | AA32: =COUNTIF('출전기록 (26)'!N$2:S$39,'2026 토탈'!X32) -> 0 | AB32: =COUNTIF($M$3:$P$40,$X32) -> 0 | AC32: =COUNTIF($Q$3:$T$40,$X32) -> 0 | AD32: =AB32+AC32 -> 0 | AE32: =AF32+AG32 -> 3 | AF32: =COUNTIF('출전기록 (26)'!W$2:AG$7,'2026 토탈'!X32)+Z32 -> 3 | AG32: =COUNTIF('출전기록 (26)'!AH$2:AM$7,'2026 토탈'!X32)+AA32 -> 0 | AH32: =COUNTIF($M$3:$P$41,$X32) -> 0 | AI32: =COUNTIF($Q$3:$T$41,$X32) -> 0 | AJ32: =AH32+AI32 -> 0
A33: K리그 | B33: 10월 9일 | C33: 금 | D33: 31 | E33: 포항 | F33: 홈 | G33: 3 | H33: 0 | I33: 승 | M33: 이민혁 | N33: 이청용 | O33: 무고사 | Q33: 이민혁 | R33: 이비자 | U33: 12189 | V33: 고형진 | X33: 김동헌 | Y33: =Z33+AA33 -> 29 | Z33: =COUNTIF('출전기록 (26)'!C$2:M$39,'2026 토탈'!X33) -> 28 | AA33: =COUNTIF('출전기록 (26)'!N$2:S$39,'2026 토탈'!X33) -> 1 | AB33: =COUNTIF($M$3:$P$40,$X33) -> 0 | AC33: =COUNTIF($Q$3:$T$40,$X33) -> 0 | AD33: =AB33+AC33 -> 0 | AE33: =AF33+AG33 -> 29 | AF33: =COUNTIF('출전기록 (26)'!W$2:AG$7,'2026 토탈'!X33)+Z33 -> 28 | AG33: =COUNTIF('출전기록 (26)'!AH$2:AM$7,'2026 토탈'!X33)+AA33 -> 1 | AH33: =COUNTIF($M$3:$P$41,$X33) -> 0 | AI33: =COUNTIF($Q$3:$T$41,$X33) -> 0 | AJ33: =AH33+AI33 -> 0
A34: K리그 | B34: 10월 18일 | C34: 일 | D34: 32 | E34: 강원 | F34: 원정 | G34: 1 | H34: 1 | I34: 무 | M34: 무고사 | U34: 5558 | V34: 설태환 | X34: 이태희 | Y34: =Z34+AA34 -> 5 | Z34: =COUNTIF('출전기록 (26)'!C$2:M$39,'2026 토탈'!X34) -> 5 | AA34: =COUNTIF('출전기록 (26)'!N$2:S$39,'2026 토탈'!X34) -> 0 | AB34: =COUNTIF($M$3:$P$40,$X34) -> 0 | AC34: =COUNTIF($Q$3:$T$40,$X34) -> 0 | AD34: =AB34+AC34 -> 0 | AE34: =AF34+AG34 -> 5 | AF34: =COUNTIF('출전기록 (26)'!W$2:AG$7,'2026 토탈'!X34)+Z34 -> 5 | AG34: =COUNTIF('출전기록 (26)'!AH$2:AM$7,'2026 토탈'!X34)+AA34 -> 0 | AH34: =COUNTIF($M$3:$P$41,$X34) -> 0 | AI34: =COUNTIF($Q$3:$T$41,$X34) -> 0 | AJ34: =AH34+AI34 -> 0
A35: K리그 | B35: 10월 24일 | C35: 토 | D35: 33 | E35: 제주 | F35: 홈 | G35: 3 | H35: 1 | I35: 승 | M35: 이명주 | N35: 이동률 | O35: 이청용 | Q35: 무고사 | R35: 페리어 | U35: 11541 | V35: 신용준 | X35: 이상현 | Y35: =Z35+AA35 -> 0 | Z35: =COUNTIF('출전기록 (26)'!C$2:M$39,'2026 토탈'!X35) -> 0 | AA35: =COUNTIF('출전기록 (26)'!N$2:S$39,'2026 토탈'!X35) -> 0 | AB35: =COUNTIF($M$3:$P$40,$X35) -> 0 | AC35: =COUNTIF($Q$3:$T$40,$X35) -> 0 | AD35: =AB35+AC35 -> 0 | AE35: =AF35+AG35 -> 0 | AF35: =COUNTIF('출전기록 (26)'!W$2:AG$7,'2026 토탈'!X35)+Z35 -> 0 | AG35: =COUNTIF('출전기록 (26)'!AH$2:AM$7,'2026 토탈'!X35)+AA35 -> 0 | AH35: =COUNTIF($M$3:$P$41,$X35) -> 0 | AI35: =COUNTIF($Q$3:$T$41,$X35) -> 0 | AJ35: =AH35+AI35 -> 0
A36: K리그 | D36: 34 | X36: 왕민준 | Y36: =Z36+AA36 -> 0 | Z36: =COUNTIF('출전기록 (26)'!C$2:M$39,'2026 토탈'!X36) -> 0 | AA36: =COUNTIF('출전기록 (26)'!N$2:S$39,'2026 토탈'!X36) -> 0 | AB36: =COUNTIF($M$3:$P$40,$X36) -> 0 | AC36: =COUNTIF($Q$3:$T$40,$X36) -> 0 | AD36: =AB36+AC36 -> 0 | AE36: =AF36+AG36 -> 0 | AF36: =COUNTIF('출전기록 (26)'!W$2:AG$7,'2026 토탈'!X36)+Z36 -> 0 | AG36: =COUNTIF('출전기록 (26)'!AH$2:AM$7,'2026 토탈'!X36)+AA36 -> 0 | AH36: =COUNTIF($M$3:$P$41,$X36) -> 0 | AI36: =COUNTIF($Q$3:$T$41,$X36) -> 0 | AJ36: =AH36+AI36 -> 0
A37: K리그 | D37: 35 | X37: 홍시후 | Y37: =Z37+AA37 -> 0 | Z37: =COUNTIF('출전기록 (26)'!C$2:M$39,'2026 토탈'!X37) -> 0 | AA37: =COUNTIF('출전기록 (26)'!N$2:S$39,'2026 토탈'!X37) -> 0 | AB37: =COUNTIF($M$3:$P$40,$X37) -> 0 | AC37: =COUNTIF($Q$3:$T$40,$X37) -> 0 | AD37: =AB37+AC37 -> 0 | AE37: =AF37+AG37 -> 0 | AF37: =COUNTIF('출전기록 (26)'!W$2:AG$7,'2026 토탈'!X37)+Z37 -> 0 | AG37: =COUNTIF('출전기록 (26)'!AH$2:AM$7,'2026 토탈'!X37)+AA37 -> 0 | AH37: =COUNTIF($M$3:$P$41,$X37) -> 0 | AI37: =COUNTIF($Q$3:$T$41,$X37) -> 0 | AJ37: =AH37+AI37 -> 0
A38: K리그 | D38: 36 | X38: 민경현 | Y38: =Z38+AA38 -> 0 | Z38: =COUNTIF('출전기록 (26)'!C$2:M$39,'2026 토탈'!X38) -> 0 | AA38: =COUNTIF('출전기록 (26)'!N$2:S$39,'2026 토탈'!X38) -> 0 | AB38: =COUNTIF($M$3:$P$40,$X38) -> 0 | AC38: =COUNTIF($Q$3:$T$40,$X38) -> 0 | AD38: =AB38+AC38 -> 0 | AE38: =AF38+AG38 -> 0 | AF38: =COUNTIF('출전기록 (26)'!W$2:AG$7,'2026 토탈'!X38)+Z38 -> 0 | AG38: =COUNTIF('출전기록 (26)'!AH$2:AM$7,'2026 토탈'!X38)+AA38 -> 0 | AH38: =COUNTIF($M$3:$P$41,$X38) -> 0 | AI38: =COUNTIF($Q$3:$T$41,$X38) -> 0 | AJ38: =AH38+AI38 -> 0
A39: K리그 | D39: 37 | X39: 성힘찬 | Y39: =Z39+AA39 -> 0 | Z39: =COUNTIF('출전기록 (26)'!C$2:M$39,'2026 토탈'!X39) -> 0 | AA39: =COUNTIF('출전기록 (26)'!N$2:S$39,'2026 토탈'!X39) -> 0 | AB39: =COUNTIF($M$3:$P$40,$X39) -> 0 | AC39: =COUNTIF($Q$3:$T$40,$X39) -> 0 | AD39: =AB39+AC39 -> 0 | AE39: =AF39+AG39 -> 0 | AF39: =COUNTIF('출전기록 (26)'!W$2:AG$7,'2026 토탈'!X39)+Z39 -> 0 | AG39: =COUNTIF('출전기록 (26)'!AH$2:AM$7,'2026 토탈'!X39)+AA39 -> 0 | AH39: =COUNTIF($M$3:$P$41,$X39) -> 0 | AI39: =COUNTIF($Q$3:$T$41,$X39) -> 0 | AJ39: =AH39+AI39 -> 0
A40: K리그 | D40: 38 | X40: 박호민 | Y40: =Z40+AA40 -> 6 | Z40: =COUNTIF('출전기록 (26)'!C$2:M$39,'2026 토탈'!X40) -> 1 | AA40: =COUNTIF('출전기록 (26)'!N$2:S$39,'2026 토탈'!X40) -> 5 | AB40: =COUNTIF($M$3:$P$40,$X40) -> 0 | AC40: =COUNTIF($Q$3:$T$40,$X40) -> 0 | AD40: =AB40+AC40 -> 0 | AE40: =AF40+AG40 -> 6 | AF40: =COUNTIF('출전기록 (26)'!W$2:AG$7,'2026 토탈'!X40)+Z40 -> 1 | AG40: =COUNTIF('출전기록 (26)'!AH$2:AM$7,'2026 토탈'!X40)+AA40 -> 5 | AH40: =COUNTIF($M$3:$P$41,$X40) -> 0 | AI40: =COUNTIF($Q$3:$T$41,$X40) -> 0 | AJ40: =AH40+AI40 -> 0
...

Sheet 출전기록 (26)
A1: 리그 | B1: 상대팀 | C1: 선발 | D1: 선발 | E1: 선발 | F1: 선발 | G1: 선발 | H1: 선발 | I1: 선발 | J1: 선발 | K1: 선발 | L1: 선발 | M1: 선발 | N1: 교체 | O1: 교체 | P1: 교체 | Q1: 교체 | R1: 교체 | S1: 교체+ | V1: FA컵 | W1: 선발 | X1: 선발 | Y1: 선발 | Z1: 선발 | AA1: 선발 | AB1: 선발 | AC1: 선발 | AD1: 선발 | AE1: 선발 | AF1: 선발 | AG1: 선발 | AH1: 교체 | AI1: 교체 | AJ1: 교체 | AK1: 교체 | AL1: 교체 | AM1: 교체
A2: 1 | B2: 서울 | C2: 김동헌 | D2: 김건희 | E2: 이비자 | F2: 김명순 | G2: 이주용 | H2: 서재민 | I2: 이케르 | J2: 제르소 | K2: 오후성 | L2: 박승호 | M2: 무고사 | N2: 이청용 | O2: 여승원 | P2: 정치인 | Q2: 이명주 | R2: 박호민
A3: 2 | B3: 광주 | C3: 김동헌 | D3: 김건희 | E3: 이비자 | F3: 김명순 | G3: 이주용 | H3: 서재민 | I3: 이명주 | J3: 제르소 | K3: 정치인 | L3: 오후성 | M3: 무고사 | N3: 이동률 | O3: 이청용 | P3: 이케르 | Q3: 박경섭 | R3: 여승원
A4: 3 | B4: 포항 | C4: 김동헌 | D4: 김건희 | E4: 이비자 | F4: 김명순 | G4: 이주용 | H4: 서재민 | I4: 이명주 | J4: 제르소 | K4: 정치인 | L4: 오후성 | M4: 무고사 | N4: 이동률 | O4: 이청용 | V4: 16강
A5: 4 | B5: 대전 | C5: 김동헌 | D5: 김건희 | E5: 이비자 | F5: 김명순 | G5: 이주용 | H5: 서재민 | I5: 이케르 | J5: 제르소 | K5: 정치인 | L5: 오후성 | M5: 무고사 | N5: 이동률 | O5: 이청용 | P5: 이명주 | Q5: 최승구 | R5: 페리어 | V5: 8강
A6: 5 | B6: 안양 | C6: 김동헌 | D6: 박경섭 | E6: 이비자 | F6: 김명순 | G6: 이주용 | H6: 서재민 | I6: 이명주 | J6: 이동률 | K6: 오후성 | L6: 박승호 | M6: 무고사 | N6: 제르소 | O6: 이청용 | P6: 최승구 | Q6: 페리어 | V6: 4강
A7: 6 | B7: 김천 | C7: 김동헌 | D7: 박경섭 | E7: 이비자 | F7: 김명순 | G7: 이주용 | H7: 서재민 | I7: 이명주 | J7: 이동률 | K7: 오후성 | L7: 박승호 | M7: 무고사 | N7: 제르소 | O7: 이청용 | P7: 정치인 | Q7: 페리어 | R7: 이케르 | V7: 결승
A8: 7 | B8: 울산 | C8: 김동헌 | D8: 박경섭 | E8: 이비자 | F8: 김명순 | G8: 이주용 | H8: 서재민 | I8: 이명주 | J8: 이동률 | K8: 오후성 | L8: 박승호 | M8: 무고사 | N8: 여승원 | O8: 제르소 | P8: 이청용 | Q8: 페리어
A9: 8 | B9: 부천 | C9: 이태희 | D9: 박경섭 | E9: 이비자 | F9: 김명순 | G9: 여승원 | H9: 서재민 | I9: 이명주 | J9: 제르소 | K9: 이청용 | L9: 페리어 | M9: 무고사 | N9: 이주용 | O9: 오후성 | P9: 정치인 | Q9: 이동률 | R9: 박호민
A10: 9 | B10: 전북 | C10: 이태희 | D10: 박경섭 | E10: 이비자 | F10: 최승구 | G10: 여승원 | H10: 서재민 | I10: 이명주 | J10: 이동률 | K10: 정치인 | L10: 페리어 | M10: 이청용 | N10: 이주용 | O10: 이케르 | P10: 제르소 | Q10: 무고사 | R10: 박호민
A11: 10 | B11: 제주 | C11: 이태희 | D11: 박경섭 | E11: 이비자 | F11: 김명순 | G11: 이주용 | H11: 서재민 | I11: 이명주 | J11: 이동률 | K11: 제르소 | L11: 이청용 | M11: 무고사 | N11: 김건희 | O11: 최승구 | P11: 이케르 | Q11: 김성민 | R11: 페리어
A12: 11 | B12: 강원 | C12: 이태희 | D12: 박경섭 | E12: 이비자 | F12: 김명순 | G12: 이주용 | H12: 서재민 | I12: 이명주 | J12: 이동률 | K12: 이청용 | L12: 페리어 | M12: 무고사 | N12: 제르소 | O12: 정치인 | P12: 이상기 | Q12: 최승구 | R12: 박호민
A13: 12 | B13: 대전 | C13: 이태희 | D13: 박경섭 | E13: 이비자 | F13: 김명순 | G13: 이상기 | H13: 서재민 | I13: 이명주 | J13: 정치인 | K13: 제르소 | L13: 박승호 | M13: 무고사 | N13: 페리어 | O13: 이동률 | P13: 이청용 | Q13: 최승구 | R13: 김동헌
A14: 13 | B14: 김천 | C14: 김동헌 | D14: 김건희 | E14: 이비자 | F14: 김명순 | G14: 이상기 | H14: 서재민 | I14: 이명주 | J14: 이동률 | K14: 이청용 | L14: 페리어 | M14: 제르소 | N14: 이주용 | O14: 박경섭 | P14: 김성민 | Q14: 정치인 | R14: 박승호
A15: 14 | B15: 포항 | C15: 김동헌 | D15: 김건희 | E15: 박경섭 | F15: 최승구 | G15: 이주용 | H15: 서재민 | I15: 정원진 | J15: 김성민 | K15: 정치인 | L15: 박승호 | M15: 박호민 | N15: 제르소 | O15: 페리어 | P15: 이동률 | Q15: 이명주 | R15: 이청용
A16: 15 | B16: 광주 | C16: 김동헌 | D16: 김건희 | E16: 이비자 | F16: 김명순 | G16: 이주용 | H16: 서재민 | I16: 이명주 | J16: 이동률 | K16: 제르소 | L16: 이청용 | M16: 페리어 | N16: 최승구 | O16: 백민규 | P16: 김성민 | Q16: 박호민 | R16: 박승호
A17: 16 | B17: 서울 | C17: 김동헌 | D17: 김건희 | E17: 이비자 | F17: 김명순 | G17: 이주용 | H17: 서재민 | I17: 이명주 | J17: 이동률 | K17: 제르소 | L17: 이청용 | M17: 페리어 | N17: 최승구 | O17: 무고사 | P17: 김성민 | Q17: 이케르 | R17: 박승호
A18: 17 | B18: 안양 | C18: 김동헌 | D18: 김건희 | E18: 이비자 | F18: 김명순 | G18: 이주용 | H18: 서재민 | I18: 김영환 | J18: 이동률 | K18: 제르소 | L18: 이청용 | M18: 페리어 | N18: 최승구 | O18: 무고사 | P18: 이케르 | Q18: 정치인
A19: 18 | B19: 전북 | C19: 김동헌 | D19: 김건희 | E19: 이비자 | F19: 김명순 | G19: 이주용 | H19: 서재민 | I19: 이명주 | J19: 이동률 | K19: 제르소 | L19: 이청용 | M19: 페리어 | N19: 최승구 | O19: 무고사 | P19: 정치인 | Q19: 이케르 | R19: 박승호
A20: 19 | B20: 울산 | C20: 김동헌 | D20: 김건희 | E20: 이비자 | F20: 김명순 | G20: 이주용 | H20: 서재민 | I20: 이명주 | J20: 김성민 | K20: 제르소 | L20: 이청용 | M20: 페리어 | N20: 최승구 | O20: 무고사 | P20: 이동률 | Q20: 김영환 | R20: 정치인
A21: 20 | B21: 부천 | C21: 김동헌 | D21: 김건희 | E21: 이비자 | F21: 김명순 | G21: 이주용 | H21: 서재민 | I21: 이명주 | J21: 김성민 | K21: 제르소 | L21: 이청용 | M21: 페리어 | N21: 최승구 | O21: 무고사 | P21: 이동률 | Q21: 정치인 | R21: 박경섭
A22: 21 | B22: 제주 | C22: 김동헌 | D22: 이비자 | E22: 김건희 | F22: 이주용 | G22: 김명순 | H22: 이명주 | I22: 제르소 | J22: 서재민 | K22: 김성민 | L22: 무고사 | M22: 이청용 | N22: 페리어 | O22: 이동률 | P22: 김영환 | Q22: 최승구 | R22: 문지환
A23: 22 | B23: 강원 | C23: 김동헌 | D23: 이비자 | E23: 김연수 | F23: 이주용 | G23: 김명순 | H23: 이명주 | I23: 김성민 | J23: 레안드로 | K23: 이청용 | L23: 무고사 | M23: 이민혁 | N23: 오후성 | O23: 제르소 | P23: 박승호
A24: 23 | B24: 김천 | C24: 김동헌 | D24: 이비자 | E24: 김건희 | F24: 이주용 | G24: 김명순 | H24: 이명주 | I24: 이동률 | J24: 제르소 | K24: 서재민 | L24: 이청용 | M24: 페리어 | N24: 무고사 | O24: 최승구 | P24: 김영환 | Q24: 정치인 | R24: 김성민
A25: 24 | B25: 광주 | C25: 김동헌 | D25: 이비자 | E25: 김건희 | F25: 이주용 | G25: 김명순 | H25: 이명주 | I25: 제르소 | J25: 서재민 | K25: 김성민 | L25: 이청용 | M25: 페리어 | N25: 최승구 | O25: 무고사 | P25: 레안드로 | Q25: 이동률 | R25: 이민혁
A26: 25 | B26: 안양 | C26: 김동헌 | D26: 이비자 | E26: 김건희 | F26: 최승구 | G26: 이주용 | H26: 이동률 | I26: 제르소 | J26: 서재민 | K26: 이민혁 | L26: 김영환 | M26: 페리어 | N26: 이청용 | O26: 무고사 | P26: 레안드로 | Q26: 이명주 | R26: 김성민
A27: 26 | B27: 전북 | C27: 김동헌 | D27: 김건희 | E27: 박경섭 | F27: 이주용 | G27: 김명순 | H27: 이명주 | I27: 이동률 | J27: 서재민 | K27: 레안드로 | L27: 무고사 | M27: 이청용 | N27: 김성민 | O27: 제르소 | P27: 페리어 | Q27: 이민혁
A28: 27 | B28: 서울 | C28: 김동헌 | D28: 이비자 | E28: 김건희 | F28: 이주용 | G28: 김명순 | H28: 이동률 | I28: 서재민 | J28: 정치인 | K28: 이민혁 | L28: 무고사 | M28: 이청용 | N28: 박경섭 | O28: 제르소 | P28: 김성민 | Q28: 페리어 | R28: 김영환
A29: 28 | B29: 부천 | C29: 김동헌 | D29: 이비자 | E29: 김연수 | F29: 이주용 | G29: 김명순 | H29: 이명주 | I29: 이동률 | J29: 서재민 | K29: 레안드로 | L29: 무고사 | M29: 페리어 | N29: 제르소 | O29: 이청용 | P29: 이민혁 | Q29: 김성민 | R29: 최승구
A30: 29 | B30: 울산 | C30: 김동헌 | D30: 이비자 | E30: 김연수 | F30: 이주용 | G30: 김명순 | H30: 이명주 | I30: 제르소 | J30: 서재민 | K30: 레안드로 | L30: 무고사 | M30: 이청용 | N30: 이동률 | O30: 김성민 | P30: 정치인 | Q30: 페리어
A31: 30 | B31: 대전 | C31: 김동헌 | D31: 이비자 | E31: 김건희 | F31: 이주용 | G31: 김명순 | H31: 이명주 | I31: 서재민 | J31: 레안드로 | K31: 이청용 | L31: 무고사 | M31: 페리어 | N31: 제르소 | O31: 최승구 | P31: 정치인 | Q31: 이민혁
A32: 31 | B32: 포항 | C32: 김동헌 | D32: 이비자 | E32: 김건희 | F32: 이주용 | G32: 김명순 | H32: 이명주 | I32: 김성민 | J32: 이민혁 | K32: 레안드로 | L32: 무고사 | M32: 이청용 | N32: 이동률 | O32: 제르소 | P32: 페리어 | Q32: 박승호 | R32: 서재민
A33: 32 | B33: 강원 | C33: 김동헌 | D33: 이주용 | E33: 이비자 | F33: 김건희 | G33: 김명순 | H33: 레안드로 | I33: 이민혁 | J33: 이명주 | K33: 이청용 | L33: 무고사 | M33: 페리어 | N33: 제르소 | O33: 김성민 | P33: 서재민 | Q33: 박승호
A34: 33 | B34: 제주 | C34: 김동헌 | D34: 이주용 | E34: 이비자 | F34: 김건희 | G34: 김명순 | H34: 레안드로 | I34: 이명주 | J34: 서재민 | K34: 김성민 | L34: 무고사 | M34: 이청용 | N34: 이동률 | O34: 페리어 | P34: 박승호 | Q34: 이민혁 | R34: 제르소
A35: 34
A36: 35
A37: 36
A38: 37
A39: 38
A41: 서재민 베스트러너 순위
...

Sheet 2025 토탈
Y1: 리그 | AB1: 리그 | AE1: 시즌 | AH1: 시즌
A2: 대회 | B2: 일자 | C2: 요일 | D2: 라운드 | E2: 상대팀 | F2: 홈/원정 | G2: 득점 | H2: 실점 | I2: 결과 | J2: 중계채널 | K2: 해설 | L2: 캐스터 | M2: 득점1 | N2: 득점2 | O2: 득점3 | P2: 득점4 | Q2: 도움1 | R2: 도움2 | S2: 도움3 | T2: 도움4 | U2: 홈 관중 | V2: 주심 | X2: 이름 | Y2: 출전 | Z2: 선발 | AA2: 교체 | AB2: 득점 | AC2: 도움 | AD2: 합계 | AE2: 출전 | AF2: 선발 | AG2: 교체 | AH2: 득점 | AI2: 도움 | AJ2: 합계 | AM2: 홈/원정 | AN2: 경기 | AO2: 승 | AP2: 무 | AQ2: 패 | AR2: 승점 | AS2: 승률 | AT2: 득점 | AU2: 실점 | AV2: 득실 | AW2: 평균 승점 | AX2: 평균 득점 | AY2: 평균 실점 | BA2: 주심 | BB2: 경기 | BC2: 승 | BD2: 무 | BE2: 패 | BF2: 승점 | BG2: 승률 | BH2: 평균승점
A3: K리그 | B3: 45710 | C3: 토 | D3: 1 | E3: 경남 | F3: 홈 | G3: 2 | H3: 0 | I3: 승 | M3: 무고사 | N3: 김성민 | Q3: 김건희 | R3: 바로우 | U3: 9363 | V3: 정희수 | X3: 무고사 | Y3: =Z3+AA3 -> 34 | Z3: =COUNTIF('출전기록 (25)'!C$2:M$39,'2025 토탈'!X3) -> 22 | AA3: =COUNTIF('출전기록 (25)'!N$2:S$39,'2025 토탈'!X3) -> 12 | AB3: =COUNTIF($M$3:$P$40,$X3) -> 20 | AC3: =COUNTIF(Q$3:T$40,X3) -> 3 | AD3: =AB3+AC3 -> 23 | AE3: =AF3+AG3 -> 34 | AF3: =COUNTIF('출전기록 (25)'!W$2:AG$7,'2025 토탈'!X3)+Z3 -> 22 | AG3: =COUNTIF('출전기록 (25)'!AH$2:AM$7,'2025 토탈'!X3)+AA3 -> 12 | AH3: =COUNTIF(M$3:P$46,$X3) -> 20 | AI3: =COUNTIF(Q$3:T$46,$X3) -> 3 | AJ3: =AH3+AI3 -> 23 | AM3: 홈 | AN3: =SUM(AO3:AQ3) -> 19 | AO3: =COUNTIFS(F3:F41,AM3,I3:I41,AO2) -> 12 | AP3: =COUNTIFS(F3:F41,AM3,I3:I41,AP2) -> 4 | AQ3: =COUNTIFS(F3:F41,AM3,I3:I41,AQ2) -> 3 | AR3: =AO3*3+AP3 -> 40 | AS3: =AO3/AN3 -> 0.63157895 | AT3: =SUMIF(F3:F41,AM3,G3:G41) -> 32 | AU3: =SUMIF(F3:F41,AM3,H3:H41) -> 12 | AV3: =AT3-AU3 -> 20 | AW3: =AR3/AN3 -> 2.1052632 | AX3: =AT3/AN3 -> 1.6842105 | AY3: =AU3/AN3 -> 0.63157895 | BA3: 정희수 | BB3: =SUM(BC3:BE3) -> 3 | BC3: =COUNTIFS(V$3:V$41,BA3,I$3:I$41,BC$2) -> 3 | BD3: =COUNTIFS(V$3:V$41,$BA3,I$3:I$41,BD$2) -> 0 | BE3: =COUNTIFS($V$3:$V$41,$BA3,$I$3:$I$41,BE$2) -> 0 | BF3: =BC3*3+BD3 -> 9 | BG3: =BC3/BB3 -> 1 | BH3: =BF3/BB3 -> 3
A4: K리그 | B4: 45717 | C4: 토 | D4: 2 | E4: 수원 | F4: 홈 | G4: 2 | H4: 0 | I4: 승 | M4: 무고사 | N4: 김성민 | Q4: 김보섭 | R4: 무고사 | U4: 18173 | V4: 박종명 | X4: 제르소 | Y4: =Z4+AA4 -> 36 | Z4: =COUNTIF('출전기록 (25)'!C$2:M$39,'2025 토탈'!X4) -> 34 | AA4: =COUNTIF('출전기록 (25)'!N$2:S$39,'2025 토탈'!X4) -> 2 | AB4: =COUNTIF($M$3:$P$40,$X4) -> 12 | AC4: =COUNTIF(Q$3:T$40,X4) -> 10 | AD4: =AB4+AC4 -> 22 | AE4: =AF4+AG4 -> 36 | AF4: =COUNTIF('출전기록 (25)'!W$2:AG$7,'2025 토탈'!X4)+Z4 -> 34 | AG4: =COUNTIF('출전기록 (25)'!AH$2:AM$7,'2025 토탈'!X4)+AA4 -> 2 | AH4: =COUNTIF(M$3:P$46,$X4) -> 12 | AI4: =COUNTIF(Q$3:T$46,$X4) -> 10 | AJ4: =AH4+AI4 -> 22 | AM4: 원정 | AN4: =SUM(AO4:AQ4) -> 20 | AO4: =COUNTIFS(F3:F41,AM4,I3:I41,AO2) -> 11 | AP4: =COUNTIFS(F3:F41,AM4,I3:I41,AP2) -> 5 | AQ4: =COUNTIFS(F3:F41,AM4,I3:I41,AQ2) -> 4 | AR4: =AO4*3+AP4 -> 38 | AS4: =AO4/AN4 -> 0.55 | AT4: =SUMIF(F3:F41,AM4,G3:G41) -> 34 | AU4: =SUMIF(F3:F41,AM4,H3:H41) -> 18 | AV4: =AT4-AU4 -> 16 | AW4: =AR4/AN4 -> 1.9 | AX4: =AT4/AN4 -> 1.7 | AY4: =AU4/AN4 -> 0.9 | BA4: 박종명 | BB4: =SUM(BC4:BE4) -> 2 | BC4: =COUNTIFS(V$3:V$41,BA4,I$3:I$41,BC$2) -> 2 | BD4: =COUNTIFS(V$3:V$41,$BA4,I$3:I$41,BD$2) -> 0 | BE4: =COUNTIFS($V$3:$V$41,$BA4,$I$3:$I$41,BE$2) -> 0 | BF4: =BC4*3+BD4 -> 6 | BG4: =BC4/BB4 -> 1 | BH4: =BF4/BB4 -> 3
A5: K리그 | B5: 45725 | C5: 일 | D5: 3 | E5: 성남 | F5: 원정 | G5: 1 | H5: 2 | I5: 패 | M5: 제르소 | Q5: 이주용 | V5: 김재홍 | X5: 바로우 | Y5: =Z5+AA5 -> 34 | Z5: =COUNTIF('출전기록 (25)'!C$2:M$39,'2025 토탈'!X5) -> 23 | AA5: =COUNTIF('출전기록 (25)'!N$2:S$39,'2025 토탈'!X5) -> 11 | AB5: =COUNTIF($M$3:$P$40,$X5) -> 3 | AC5: =COUNTIF(Q$3:T$40,X5) -> 3 | AD5: =AB5+AC5 -> 6 | AE5: =AF5+AG5 -> 34 | AF5: =COUNTIF('출전기록 (25)'!W$2:AG$7,'2025 토탈'!X5)+Z5 -> 23 | AG5: =COUNTIF('출전기록 (25)'!AH$2:AM$7,'2025 토탈'!X5)+AA5 -> 11 | AH5: =COUNTIF(M$3:P$46,$X5) -> 3 | AI5: =COUNTIF(Q$3:T$46,$X5) -> 3 | AJ5: =AH5+AI5 -> 6 | AM5: 총합 | AN5: =SUM(AN3:AN4) -> 39 | AO5: =SUM(AO3:AO4) -> 23 | AP5: =SUM(AP3:AP4) -> 9 | AQ5: =SUM(AQ3:AQ4) -> 7 | AR5: =SUM(AR3:AR4) -> 78 | AS5: =AO5/AN5 -> 0.58974359 | AT5: =SUM(AT3:AT4) -> 66 | AU5: =SUM(AU3:AU4) -> 30 | AV5: =SUM(AV3:AV4) -> 36 | AW5: =AR5/AN5 -> 2 | AX5: =AT5/AN5 -> 1.6923077 | AY5: =AU5/AN5 -> 0.76923077 | BA5: 김재홍 | BB5: =SUM(BC5:BE5) -> 2 | BC5: =COUNTIFS(V$3:V$41,BA5,I$3:I$41,BC$2) -> 1 | BD5: =COUNTIFS(V$3:V$41,$BA5,I$3:I$41,BD$2) -> 0 | BE5: =COUNTIFS($V$3:$V$41,$BA5,$I$3:$I$41,BE$2) -> 1 | BF5: =BC5*3+BD5 -> 3 | BG5: =BC5/BB5 -> 0.5 | BH5: =BF5/BB5 -> 1.5
A6: K리그 | B6: 45731 | C6: 토 | D6: 4 | E6: 서울E | F6: 홈 | G6: 1 | H6: 0 | I6: 승 | M6: 무고사 | U6: 9695 | V6: 조지음 | X6: 박승호 | Y6: =Z6+AA6 -> 36 | Z6: =COUNTIF('출전기록 (25)'!C$2:M$39,'2025 토탈'!X6) -> 34 | AA6: =COUNTIF('출전기록 (25)'!N$2:S$39,'2025 토탈'!X6) -> 2 | AB6: =COUNTIF($M$3:$P$40,$X6) -> 9 | AC6: =COUNTIF(Q$3:T$40,X6) -> 1 | AD6: =AB6+AC6 -> 10 | AE6: =AF6+AG6 -> 36 | AF6: =COUNTIF('출전기록 (25)'!W$2:AG$7,'2025 토탈'!X6)+Z6 -> 34 | AG6: =COUNTIF('출전기록 (25)'!AH$2:AM$7,'2025 토탈'!X6)+AA6 -> 2 | AH6: =COUNTIF(M$3:P$46,$X6) -> 9 | AI6: =COUNTIF(Q$3:T$46,$X6) -> 1 | AJ6: =AH6+AI6 -> 10 | AM6: 팀명 | AN6: 경기 | AO6: 승 | AP6: 무 | AQ6: 패 | AR6: 승점 | AS6: 승률 | AT6: 득점 | AU6: 실점 | AV6: 득실 | BA6: 조지음 | BB6: =SUM(BC6:BE6) -> 1 | BC6: =COUNTIFS(V$3:V$41,BA6,I$3:I$41,BC$2) -> 1 | BD6: =COUNTIFS(V$3:V$41,$BA6,I$3:I$41,BD$2) -> 0 | BE6: =COUNTIFS($V$3:$V$41,$BA6,$I$3:$I$41,BE$2) -> 0 | BF6: =BC6*3+BD6 -> 3 | BG6: =BC6/BB6 -> 1 | BH6: =BF6/BB6 -> 3
A7: K리그 | B7: 45745 | C7: 토 | D7: 5 | E7: 부산 | F7: 홈 | G7: 1 | H7: 1 | I7: 무 | M7: 무고사 | U7: 8507 | V7: 정동식 | X7: 김보섭 | Y7: =Z7+AA7 -> 19 | Z7: =COUNTIF('출전기록 (25)'!C$2:M$39,'2025 토탈'!X7) -> 7 | AA7: =COUNTIF('출전기록 (25)'!N$2:S$39,'2025 토탈'!X7) -> 12 | AB7: =COUNTIF($M$3:$P$40,$X7) -> 0 | AC7: =COUNTIF(Q$3:T$40,X7) -> 4 | AD7: =AB7+AC7 -> 4 | AE7: =AF7+AG7 -> 21 | AF7: =COUNTIF('출전기록 (25)'!W$2:AG$7,'2025 토탈'!X7)+Z7 -> 9 | AG7: =COUNTIF('출전기록 (25)'!AH$2:AM$7,'2025 토탈'!X7)+AA7 -> 12 | AH7: =COUNTIF(M$3:P$46,$X7) -> 0 | AI7: =COUNTIF(Q$3:T$46,$X7) -> 5 | AJ7: =AH7+AI7 -> 5 | AL7: K리그 | AM7: 경남 | AN7: =SUM(AO7:AQ7) -> 3 | AO7: =COUNTIFS(A:A,AL7,E:E,AM7,I:I,"승") -> 3 | AP7: =COUNTIFS(A:A,AL7,E:E,AM7,I:I,"무") -> 0 | AQ7: =COUNTIFS(A:A,AL7,E:E,AM7,I:I,"패") -> 0 | AR7: =AO7*3+AP7 -> 9 | AS7: =AO7/AN7 -> 1 | AT7: =SUMIF(E:E,AM7,G:G) -> 7 | AU7: =SUMIF(E:E,AM7,H:H) -> 0 | AV7: =AT7-AU7 -> 7 | BA7: 정동식 | BB7: =SUM(BC7:BE7) -> 6 | BC7: =COUNTIFS(V$3:V$41,BA7,I$3:I$41,BC$2) -> 2 | BD7: =COUNTIFS(V$3:V$41,$BA7,I$3:I$41,BD$2) -> 3 | BE7: =COUNTIFS($V$3:$V$41,$BA7,$I$3:$I$41,BE$2) -> 1 | BF7: =BC7*3+BD7 -> 9 | BG7: =BC7/BB7 -> 0.33333333 | BH7: =BF7/BB7 -> 1.5
A8: K리그 | B8: 45752 | C8: 토 | D8: 6 | E8: 화성 | F8: 원정 | G8: 1 | H8: 0 | I8: 승 | M8: 이동률 | V8: 오현진 | X8: 김성민 | Y8: =Z8+AA8 -> 29 | Z8: =COUNTIF('출전기록 (25)'!C$2:M$39,'2025 토탈'!X8) -> 7 | AA8: =COUNTIF('출전기록 (25)'!N$2:S$39,'2025 토탈'!X8) -> 22 | AB8: =COUNTIF($M$3:$P$40,$X8) -> 2 | AC8: =COUNTIF(Q$3:T$40,X8) -> 0 | AD8: =AB8+AC8 -> 2 | AE8: =AF8+AG8 -> 31 | AF8: =COUNTIF('출전기록 (25)'!W$2:AG$7,'2025 토탈'!X8)+Z8 -> 8 | AG8: =COUNTIF('출전기록 (25)'!AH$2:AM$7,'2025 토탈'!X8)+AA8 -> 23 | AH8: =COUNTIF(M$3:P$46,$X8) -> 3 | AI8: =COUNTIF(Q$3:T$46,$X8) -> 0 | AJ8: =AH8+AI8 -> 3 | AL8: K리그 | AM8: 수원 | AN8: =SUM(AO8:AQ8) -> 3 | AO8: =COUNTIFS(A:A,AL8,E:E,AM8,I:I,"승") -> 2 | AP8: =COUNTIFS(A:A,AL8,E:E,AM8,I:I,"무") -> 1 | AQ8: =COUNTIFS(A:A,AL8,E:E,AM8,I:I,"패") -> 0 | AR8: =AO8*3+AP8 -> 7 | AS8: =AO8/AN8 -> 0.66666667 | AT8: =SUMIF(E:E,AM8,G:G) -> 5 | AU8: =SUMIF(E:E,AM8,H:H) -> 2 | AV8: =AT8-AU8 -> 3 | BA8: 오현진 | BB8: =SUM(BC8:BE8) -> 3 | BC8: =COUNTIFS(V$3:V$41,BA8,I$3:I$41,BC$2) -> 2 | BD8: =COUNTIFS(V$3:V$41,$BA8,I$3:I$41,BD$2) -> 0 | BE8: =COUNTIFS($V$3:$V$41,$BA8,$I$3:$I$41,BE$2) -> 1 | BF8: =BC8*3+BD8 -> 6 | BG8: =BC8/BB8 -> 0.66666667 | BH8: =BF8/BB8 -> 2
A9: K리그 | B9: 45760 | C9: 일 | D9: 7 | E9: 충북청주 | F9: 홈 | G9: 2 | H9: 1 | I9: 승 | M9: 이동률 | N9: 무고사 | Q9: 김명순 | U9: 5542 | V9: 박세진 | X9: 이동률 | Y9: =Z9+AA9 -> 8 | Z9: =COUNTIF('출전기록 (25)'!C$2:M$39,'2025 토탈'!X9) -> 2 | AA9: =COUNTIF('출전기록 (25)'!N$2:S$39,'2025 토탈'!X9) -> 6 | AB9: =COUNTIF($M$3:$P$40,$X9) -> 3 | AC9: =COUNTIF(Q$3:T$40,X9) -> 0 | AD9: =AB9+AC9 -> 3 | AE9: =AF9+AG9 -> 8 | AF9: =COUNTIF('출전기록 (25)'!W$2:AG$7,'2025 토탈'!X9)+Z9 -> 2 | AG9: =COUNTIF('출전기록 (25)'!AH$2:AM$7,'2025 토탈'!X9)+AA9 -> 6 | AH9: =COUNTIF(M$3:P$46,$X9) -> 3 | AI9: =COUNTIF(Q$3:T$46,$X9) -> 0 | AJ9: =AH9+AI9 -> 3 | AL9: K리그 | AM9: 성남 | AN9: =SUM(AO9:AQ9) -> 3 | AO9: =COUNTIFS(A:A,AL9,E:E,AM9,I:I,"승") -> 0 | AP9: =COUNTIFS(A:A,AL9,E:E,AM9,I:I,"무") -> 1 | AQ9: =COUNTIFS(A:A,AL9,E:E,AM9,I:I,"패") -> 2 | AR9: =AO9*3+AP9 -> 1 | AS9: =AO9/AN9 -> 0 | AT9: =SUMIF(E:E,AM9,G:G) -> 4 | AU9: =SUMIF(E:E,AM9,H:H) -> 6 | AV9: =AT9-AU9 -> -2 | BA9: 박세진 | BB9: =SUM(BC9:BE9) -> 2 | BC9: =COUNTIFS(V$3:V$41,BA9,I$3:I$41,BC$2) -> 2 | BD9: =COUNTIFS(V$3:V$41,$BA9,I$3:I$41,BD$2) -> 0 | BE9: =COUNTIFS($V$3:$V$41,$BA9,$I$3:$I$41,BE$2) -> 0 | BF9: =BC9*3+BD9 -> 6 | BG9: =BC9/BB9 -> 1 | BH9: =BF9/BB9 -> 3
A10: K리그 | B10: 45766 | C10: 토 | D10: 8 | E10: 천안 | F10: 홈 | G10: 3 | H10: 0 | I10: 승 | M10: 무고사 | N10: 무고사 | O10: 이동률 | Q10: 김명순 | R10: 제르소 | U10: 4637 | V10: 정희수 | X10: 김민석 | Y10: =Z10+AA10 -> 22 | Z10: =COUNTIF('출전기록 (25)'!C$2:M$39,'2025 토탈'!X10) -> 4 | AA10: =COUNTIF('출전기록 (25)'!N$2:S$39,'2025 토탈'!X10) -> 18 | AB10: =COUNTIF($M$3:$P$40,$X10) -> 1 | AC10: =COUNTIF(Q$3:T$40,X10) -> 0 | AD10: =AB10+AC10 -> 1 | AE10: =AF10+AG10 -> 24 | AF10: =COUNTIF('출전기록 (25)'!W$2:AG$7,'2025 토탈'!X10)+Z10 -> 6 | AG10: =COUNTIF('출전기록 (25)'!AH$2:AM$7,'2025 토탈'!X10)+AA10 -> 18 | AH10: =COUNTIF(M$3:P$46,$X10) -> 1 | AI10: =COUNTIF(Q$3:T$46,$X10) -> 2 | AJ10: =AH10+AI10 -> 3 | AL10: K리그 | AM10: 서울E | AN10: =SUM(AO10:AQ10) -> 3 | AO10: =COUNTIFS(A:A,AL10,E:E,AM10,I:I,"승") -> 1 | AP10: =COUNTIFS(A:A,AL10,E:E,AM10,I:I,"무") -> 2 | AQ10: =COUNTIFS(A:A,AL10,E:E,AM10,I:I,"패") -> 0 | AR10: =AO10*3+AP10 -> 5 | AS10: =AO10/AN10 -> 0.33333333 | AT10: =SUMIF(E:E,AM10,G:G) -> 1 | AU10: =SUMIF(E:E,AM10,H:H) -> 0 | AV10: =AT10-AU10 -> 1 | BA10: 고민국 | BB10: =SUM(BC10:BE10) -> 3 | BC10: =COUNTIFS(V$3:V$41,BA10,I$3:I$41,BC$2) -> 3 | BD10: =COUNTIFS(V$3:V$41,$BA10,I$3:I$41,BD$2) -> 0 | BE10: =COUNTIFS($V$3:$V$41,$BA10,$I$3:$I$41,BE$2) -> 0 | BF10: =BC10*3+BD10 -> 9 | BG10: =BC10/BB10 -> 1 | BH10: =BF10/BB10 -> 3
A11: K리그 | B11: 45773 | C11: 토 | D11: 9 | E11: 부천 | F11: 원정 | G11: 3 | H11: 1 | I11: 승 | M11: 박승호 | N11: 이명주 | O11: 무고사 | Q11: 무고사 | R11: 제르소 | S11: 제르소 | V11: 박종명 | X11: 백민규 | Y11: =Z11+AA11 -> 3 | Z11: =COUNTIF('출전기록 (25)'!C$2:M$39,'2025 토탈'!X11) -> 3 | AA11: =COUNTIF('출전기록 (25)'!N$2:S$39,'2025 토탈'!X11) -> 0 | AB11: =COUNTIF($M$3:$P$40,$X11) -> 0 | AC11: =COUNTIF(Q$3:T$40,X11) -> 0 | AD11: =AB11+AC11 -> 0 | AE11: =AF11+AG11 -> 6 | AF11: =COUNTIF('출전기록 (25)'!W$2:AG$7,'2025 토탈'!X11)+Z11 -> 5 | AG11: =COUNTIF('출전기록 (25)'!AH$2:AM$7,'2025 토탈'!X11)+AA11 -> 1 | AH11: =COUNTIF(M$3:P$46,$X11) -> 0 | AI11: =COUNTIF(Q$3:T$46,$X11) -> 0 | AJ11: =AH11+AI11 -> 0 | AL11: K리그 | AM11: 부산 | AN11: =SUM(AO11:AQ11) -> 3 | AO11: =COUNTIFS(A:A,AL11,E:E,AM11,I:I,"승") -> 1 | AP11: =COUNTIFS(A:A,AL11,E:E,AM11,I:I,"무") -> 2 | AQ11: =COUNTIFS(A:A,AL11,E:E,AM11,I:I,"패") -> 0 | AR11: =AO11*3+AP11 -> 5 | AS11: =AO11/AN11 -> 0.33333333 | AT11: =SUMIF(E:E,AM11,G:G) -> 3 | AU11: =SUMIF(E:E,AM11,H:H) -> 1 | AV11: =AT11-AU11 -> 2 | BA11: 정회수 | BB11: =SUM(BC11:BE11) -> 1 | BC11: =COUNTIFS(V$3:V$41,BA11,I$3:I$41,BC$2) -> 1 | BD11: =COUNTIFS(V$3:V$41,$BA11,I$3:I$41,BD$2) -> 0 | BE11: =COUNTIFS($V$3:$V$41,$BA11,$I$3:$I$41,BE$2) -> 0 | BF11: =BC11*3+BD11 -> 3 | BG11: =BC11/BB11 -> 1 | BH11: =BF11/BB11 -> 3
A12: K리그 | B12: 45781 | C12: 일 | D12: 10 | E12: 김포 | F12: 홈 | G12: 3 | H12: 0 | I12: 승 | M12: 박경섭 | N12: 무고사 | O12: 김민석 | S12: 이주용 | U12: 11792 | V12: 고민국 | X12: 박호민 | Y12: =Z12+AA12 -> 24 | Z12: =COUNTIF('출전기록 (25)'!C$2:M$39,'2025 토탈'!X12) -> 8 | AA12: =COUNTIF('출전기록 (25)'!N$2:S$39,'2025 토탈'!X12) -> 16 | AB12: =COUNTIF($M$3:$P$40,$X12) -> 5 | AC12: =COUNTIF(Q$3:T$40,X12) -> 0 | AD12: =AB12+AC12 -> 5 | AE12: =AF12+AG12 -> 27 | AF12: =COUNTIF('출전기록 (25)'!W$2:AG$7,'2025 토탈'!X12)+Z12 -> 10 | AG12: =COUNTIF('출전기록 (25)'!AH$2:AM$7,'2025 토탈'!X12)+AA12 -> 17 | AH12: =COUNTIF(M$3:P$46,$X12) -> 7 | AI12: =COUNTIF(Q$3:T$46,$X12) -> 0 | AJ12: =AH12+AI12 -> 7 | AL12: K리그 | AM12: 화성 | AN12: =SUM(AO12:AQ12) -> 3 | AO12: =COUNTIFS(A:A,AL12,E:E,AM12,I:I,"승") -> 3 | AP12: =COUNTIFS(A:A,AL12,E:E,AM12,I:I,"무") -> 0 | AQ12: =COUNTIFS(A:A,AL12,E:E,AM12,I:I,"패") -> 0 | AR12: =AO12*3+AP12 -> 9 | AS12: =AO12/AN12 -> 1 | AT12: =SUMIF(E:E,AM12,G:G) -> 4 | AU12: =SUMIF(E:E,AM12,H:H) -> 0 | AV12: =AT12-AU12 -> 4 | BA12: 최철준 | BB12: =SUM(BC12:BE12) -> 3 | BC12: =COUNTIFS(V$3:V$41,BA12,I$3:I$41,BC$2) -> 1 | BD12: =COUNTIFS(V$3:V$41,$BA12,I$3:I$41,BD$2) -> 2 | BE12: =COUNTIFS($V$3:$V$41,$BA12,$I$3:$I$41,BE$2) -> 0 | BF12: =BC12*3+BD12 -> 5 | BG12: =BC12/BB12 -> 0.33333333 | BH12: =BF12/BB12 -> 1.6666667
A13: K리그 | B13: 45787 | C13: 토 | D13: 11 | E13: 충남아산 | F13: 원정 | G13: 3 | H13: 0 | I13: 승 | M13: 제르소 | N13: 바로우 | O13: 제르소 | Q13: 이명주 | R13: 무고사 | S13: 바로우 | V13: 김재홍 | X13: 쇼타 | Y13: =Z13+AA13 -> 0 | Z13: =COUNTIF('출전기록 (25)'!C$2:M$39,'2025 토탈'!X13) -> 0 | AA13: =COUNTIF('출전기록 (25)'!N$2:S$39,'2025 토탈'!X13) -> 0 | AB13: =COUNTIF($M$3:$P$40,$X13) -> 0 | AC13: =COUNTIF(Q$3:T$40,X13) -> 0 | AD13: =AB13+AC13 -> 0 | AE13: =AF13+AG13 -> 3 | AF13: =COUNTIF('출전기록 (25)'!W$2:AG$7,'2025 토탈'!X13)+Z13 -> 1 | AG13: =COUNTIF('출전기록 (25)'!AH$2:AM$7,'2025 토탈'!X13)+AA13 -> 2 | AH13: =COUNTIF(M$3:P$46,$X13) -> 0 | AI13: =COUNTIF(Q$3:T$46,$X13) -> 0 | AJ13: =AH13+AI13 -> 0 | AL13: K리그 | AM13: 충북청주 | AN13: =SUM(AO13:AQ13) -> 3 | AO13: =COUNTIFS(A:A,AL13,E:E,AM13,I:I,"승") -> 2 | AP13: =COUNTIFS(A:A,AL13,E:E,AM13,I:I,"무") -> 0 | AQ13: =COUNTIFS(A:A,AL13,E:E,AM13,I:I,"패") -> 1 | AR13: =AO13*3+AP13 -> 6 | AS13: =AO13/AN13 -> 0.66666667 | AT13: =SUMIF(E:E,AM13,G:G) -> 6 | AU13: =SUMIF(E:E,AM13,H:H) -> 2 | AV13: =AT13-AU13 -> 4 | BA13: 원명희 | BB13: =SUM(BC13:BE13) -> 1 | BC13: =COUNTIFS(V$3:V$41,BA13,I$3:I$41,BC$2) -> 0 | BD13: =COUNTIFS(V$3:V$41,$BA13,I$3:I$41,BD$2) -> 1 | BE13: =COUNTIFS($V$3:$V$41,$BA13,$I$3:$I$41,BE$2) -> 0 | BF13: =BC13*3+BD13 -> 1 | BG13: =BC13/BB13 -> 0 | BH13: =BF13/BB13 -> 1
A14: K리그 | B14: 45795 | C14: 일 | D14: 12 | E14: 안산 | F14: 원정 | G14: 2 | H14: 0 | I14: 승 | M14: 무고사 | N14: 박승호 | R14: 제르소 | V14: 박세진 | X14: 강민성 | Y14: =Z14+AA14 -> 0 | Z14: =COUNTIF('출전기록 (25)'!C$2:M$39,'2025 토탈'!X14) -> 0 | AA14: =COUNTIF('출전기록 (25)'!N$2:S$39,'2025 토탈'!X14) -> 0 | AB14: =COUNTIF($M$3:$P$40,$X14) -> 0 | AC14: =COUNTIF(Q$3:T$40,X14) -> 0 | AD14: =AB14+AC14 -> 0 | AE14: =AF14+AG14 -> 1 | AF14: =COUNTIF('출전기록 (25)'!W$2:AG$7,'2025 토탈'!X14)+Z14 -> 0 | AG14: =COUNTIF('출전기록 (25)'!AH$2:AM$7,'2025 토탈'!X14)+AA14 -> 1 | AH14: =COUNTIF(M$3:P$46,$X14) -> 0 | AI14: =COUNTIF(Q$3:T$46,$X14) -> 0 | AJ14: =AH14+AI14 -> 0 | AL14: K리그 | AM14: 천안 | AN14: =SUM(AO14:AQ14) -> 3 | AO14: =COUNTIFS(A:A,AL14,E:E,AM14,I:I,"승") -> 2 | AP14: =COUNTIFS(A:A,AL14,E:E,AM14,I:I,"무") -> 1 | AQ14: =COUNTIFS(A:A,AL14,E:E,AM14,I:I,"패") -> 0 | AR14: =AO14*3+AP14 -> 7 | AS14: =AO14/AN14 -> 0.66666667 | AT14: =SUMIF(E:E,AM14,G:G) -> 10 | AU14: =SUMIF(E:E,AM14,H:H) -> 6 | AV14: =AT14-AU14 -> 4 | BA14: 이경순 | BB14: =SUM(BC14:BE14) -> 1 | BC14: =COUNTIFS(V$3:V$41,BA14,I$3:I$41,BC$2) -> 1 | BD14: =COUNTIFS(V$3:V$41,$BA14,I$3:I$41,BD$2) -> 0 | BE14: =COUNTIFS($V$3:$V$41,$BA14,$I$3:$I$41,BE$2) -> 0 | BF14: =BC14*3+BD14 -> 3 | BG14: =BC14/BB14 -> 1 | BH14: =BF14/BB14 -> 3
A15: K리그 | B15: 45802 | C15: 일 | D15: 13 | E15: 전남 | F15: 홈 | G15: 2 | H15: 0 | I15: 승 | M15: 무고사 | N15: 무고사 | U15: 12052 | V15: 정동식 | X15: 서동한 | Y15: =Z15+AA15 -> 0 | Z15: =COUNTIF('출전기록 (25)'!C$2:M$39,'2025 토탈'!X15) -> 0 | AA15: =COUNTIF('출전기록 (25)'!N$2:S$39,'2025 토탈'!X15) -> 0 | AB15: =COUNTIF($M$3:$P$40,$X15) -> 0 | AC15: =COUNTIF(Q$3:T$40,X15) -> 0 | AD15: =AB15+AC15 -> 0 | AE15: =AF15+AG15 -> 2 | AF15: =COUNTIF('출전기록 (25)'!W$2:AG$7,'2025 토탈'!X15)+Z15 -> 1 | AG15: =COUNTIF('출전기록 (25)'!AH$2:AM$7,'2025 토탈'!X15)+AA15 -> 1 | AH15: =COUNTIF(M$3:P$46,$X15) -> 0 | AI15: =COUNTIF(Q$3:T$46,$X15) -> 0 | AJ15: =AH15+AI15 -> 0 | AL15: K리그 | AM15: 부천 | AN15: =SUM(AO15:AQ15) -> 3 | AO15: =COUNTIFS(A:A,AL15,E:E,AM15,I:I,"승") -> 2 | AP15: =COUNTIFS(A:A,AL15,E:E,AM15,I:I,"무") -> 0 | AQ15: =COUNTIFS(A:A,AL15,E:E,AM15,I:I,"패") -> 1 | AR15: =AO15*3+AP15 -> 6 | AS15: =AO15/AN15 -> 0.66666667 | AT15: =SUMIF(E:E,AM15,G:G) -> 4 | AU15: =SUMIF(E:E,AM15,H:H) -> 2 | AV15: =AT15-AU15 -> 2 | BA15: 박진호 | BB15: =SUM(BC15:BE15) -> 1 | BC15: =COUNTIFS(V$3:V$41,BA15,I$3:I$41,BC$2) -> 1 | BD15: =COUNTIFS(V$3:V$41,$BA15,I$3:I$41,BD$2) -> 0 | BE15: =COUNTIFS($V$3:$V$41,$BA15,$I$3:$I$41,BE$2) -> 0 | BF15: =BC15*3+BD15 -> 3 | BG15: =BC15/BB15 -> 1 | BH15: =BF15/BB15 -> 3
A16: K리그 | B16: 45809 | C16: 일 | D16: 14 | E16: 천안 | F16: 원정 | G16: 3 | H16: 3 | I16: 무 | M16: 자책골 | N16: 무고사 | O16: 제르소 | V16: 최철준 | X16: 성힘찬 | Y16: =Z16+AA16 -> 0 | Z16: =COUNTIF('출전기록 (25)'!C$2:M$39,'2025 토탈'!X16) -> 0 | AA16: =COUNTIF('출전기록 (25)'!N$2:S$39,'2025 토탈'!X16) -> 0 | AB16: =COUNTIF($M$3:$P$40,$X16) -> 0 | AC16: =COUNTIF(Q$3:T$40,X16) -> 0 | AD16: =AB16+AC16 -> 0 | AE16: =AF16+AG16 -> 0 | AF16: =COUNTIF('출전기록 (25)'!W$2:AG$7,'2025 토탈'!X16)+Z16 -> 0 | AG16: =COUNTIF('출전기록 (25)'!AH$2:AM$7,'2025 토탈'!X16)+AA16 -> 0 | AH16: =COUNTIF(M$3:P$46,$X16) -> 0 | AI16: =COUNTIF(Q$3:T$46,$X16) -> 0 | AJ16: =AH16+AI16 -> 0 | AL16: K리그 | AM16: 김포 | AN16: =SUM(AO16:AQ16) -> 3 | AO16: =COUNTIFS(A:A,AL16,E:E,AM16,I:I,"승") -> 1 | AP16: =COUNTIFS(A:A,AL16,E:E,AM16,I:I,"무") -> 1 | AQ16: =COUNTIFS(A:A,AL16,E:E,AM16,I:I,"패") -> 1 | AR16: =AO16*3+AP16 -> 4 | AS16: =AO16/AN16 -> 0.33333333 | AT16: =SUMIF(E:E,AM16,G:G) -> 5 | AU16: =SUMIF(E:E,AM16,H:H) -> 3 | AV16: =AT16-AU16 -> 2 | BA16: 오현정 | BB16: =SUM(BC16:BE16) -> 3 | BC16: =COUNTIFS(V$3:V$41,BA16,I$3:I$41,BC$2) -> 1 | BD16: =COUNTIFS(V$3:V$41,$BA16,I$3:I$41,BD$2) -> 1 | BE16: =COUNTIFS($V$3:$V$41,$BA16,$I$3:$I$41,BE$2) -> 1 | BF16: =BC16*3+BD16 -> 4 | BG16: =BC16/BB16 -> 0.33333333 | BH16: =BF16/BB16 -> 1.3333333
A17: K리그 | B17: 45816 | C17: 일 | D17: 15 | E17: 부천 | F17: 홈 | G17: 1 | H17: 0 | I17: 승 | M17: 제르소 | U17: 11007 | V17: 오현진 | X17: 이명주 | Y17: =Z17+AA17 -> 34 | Z17: =COUNTIF('출전기록 (25)'!C$2:M$39,'2025 토탈'!X17) -> 34 | AA17: =COUNTIF('출전기록 (25)'!N$2:S$39,'2025 토탈'!X17) -> 0 | AB17: =COUNTIF($M$3:$P$40,$X17) -> 2 | AC17: =COUNTIF(Q$3:T$40,X17) -> 3 | AD17: =AB17+AC17 -> 5 | AE17: =AF17+AG17 -> 34 | AF17: =COUNTIF('출전기록 (25)'!W$2:AG$7,'2025 토탈'!X17)+Z17 -> 34 | AG17: =COUNTIF('출전기록 (25)'!AH$2:AM$7,'2025 토탈'!X17)+AA17 -> 0 | AH17: =COUNTIF(M$3:P$46,$X17) -> 2 | AI17: =COUNTIF(Q$3:T$46,$X17) -> 3 | AJ17: =AH17+AI17 -> 5 | AL17: K리그 | AM17: 충남아산 | AN17: =SUM(AO17:AQ17) -> 3 | AO17: =COUNTIFS(A:A,AL17,E:E,AM17,I:I,"승") -> 2 | AP17: =COUNTIFS(A:A,AL17,E:E,AM17,I:I,"무") -> 1 | AQ17: =COUNTIFS(A:A,AL17,E:E,AM17,I:I,"패") -> 0 | AR17: =AO17*3+AP17 -> 7 | AS17: =AO17/AN17 -> 0.66666667 | AT17: =SUMIF(E:E,AM17,G:G) -> 6 | AU17: =SUMIF(E:E,AM17,H:H) -> 2 | AV17: =AT17-AU17 -> 4 | BA17: 최광호 | BB17: =SUM(BC17:BE17) -> 2 | BC17: =COUNTIFS(V$3:V$41,BA17,I$3:I$41,BC$2) -> 1 | BD17: =COUNTIFS(V$3:V$41,$BA17,I$3:I$41,BD$2) -> 1 | BE17: =COUNTIFS($V$3:$V$41,$BA17,$I$3:$I$41,BE$2) -> 0 | BF17: =BC17*3+BD17 -> 4 | BG17: =BC17/BB17 -> 0.5 | BH17: =BF17/BB17 -> 2
